Workbook

Sheet Engagement Metadata
A1: The Performance Equation - Diagnostic Workbook
A2: Scoring engine - one workbook per unit. Enter data only in shaded input cells; all other cells calculate automatically.
A4: Cell legend
A5: INPUT - you type here | B5: Calculated - do not edit | D5: Three input types ↓
A6: Type A - raw survey item means (1.00–5.00); the workbook reverse-scores and converts.
A7: Type B - structured counts; apply any provider-specific Tier-2 adjustment BEFORE entry, then the workbook does the final formula.
A8: Type C - finished 0–100 score computed OUTSIDE the workbook (module / platform / audit rule); the workbook uses it as given.
A10: Engagement details
A11: Client name | D11: Northwind Mutual
A12: Unit name | D12: Member Services
A13: Unit FTE | D13: 60
A14: ANZSIC sector (metadata only) | D14: K - Financial and Insurance Services
A15: Sub-sector | D15: Health insurance
A16: Size band | D16: 200–1,000 FTE
A17: Unit type | D17: Customer-facing service
A18: Industry archetype (drives within-component weights) | D18: Default
A19: Engagement date | D19: 46174
A20: Lead analyst | D20: M. (PerformanceVP)
A21: Source Diagnostic reference (used by Intervention Design Workbook) | D21: PVP-2026-NWM-MS

Sheet Tier Assignment
A1: Tier Assignment
A2: Per sub-dimension: the measurement route used, source, vintage. Confidence is computed from vintage against the sub-dimension's cadence window.
A4: Sub-dimension | B4: Tier selector | C4: Source identifier | D4: Vintage (data date) | E4: Confidence | F4: Notes
A5: C1 - Skill | B5: Tier 1 | C5: Workday Skills Cloud + internal 360 | D5: 46127 | E5: =IFERROR(IF(B5="Insufficient data","n/a",IF(DATEDIF(D5,'Engagement Metadata'!$D$19,"m")<=INDEX(Ref!$B$41:$B$61,MATCH("C1",Ref!$A$41:$A$61,0)),"High",IF(DATEDIF(D5,'Engagement Metadata'!$D$19,"m")<=INDEX(Ref!$C$41:$C$61,MATCH("C1",Ref!$A$41:$A$61,0)),"Medium","Low"))),"-") -> High | F5: Tech via T1, behavioural via T2 360
A6: C2 - Knowledge | B6: Tier 1 | C6: Sentrient + internal knowledge test | D6: 46132 | E6: =IFERROR(IF(B6="Insufficient data","n/a",IF(DATEDIF(D6,'Engagement Metadata'!$D$19,"m")<=INDEX(Ref!$B$41:$B$61,MATCH("C2",Ref!$A$41:$A$61,0)),"High",IF(DATEDIF(D6,'Engagement Metadata'!$D$19,"m")<=INDEX(Ref!$C$41:$C$61,MATCH("C2",Ref!$A$41:$A$61,0)),"Medium","Low"))),"-") -> High
A7: C3 - Talent density | B7: Tier 1 | C7: Workday calibrated ratings | D7: 46111 | E7: =IFERROR(IF(B7="Insufficient data","n/a",IF(DATEDIF(D7,'Engagement Metadata'!$D$19,"m")<=INDEX(Ref!$B$41:$B$61,MATCH("C3",Ref!$A$41:$A$61,0)),"High",IF(DATEDIF(D7,'Engagement Metadata'!$D$19,"m")<=INDEX(Ref!$C$41:$C$61,MATCH("C3",Ref!$A$41:$A$61,0)),"Medium","Low"))),"-") -> High | F7: Documented calibration
A8: C4 - Collective intelligence | B8: Tier 3 | C8: CII (PerformanceVP) | D8: 46152 | E8: =IFERROR(IF(B8="Insufficient data","n/a",IF(DATEDIF(D8,'Engagement Metadata'!$D$19,"m")<=INDEX(Ref!$B$41:$B$61,MATCH("C4",Ref!$A$41:$A$61,0)),"High",IF(DATEDIF(D8,'Engagement Metadata'!$D$19,"m")<=INDEX(Ref!$C$41:$C$61,MATCH("C4",Ref!$A$41:$A$61,0)),"Medium","Low"))),"-") -> High | F8: Unit-level CII
A9: C5 - Learning velocity | B9: Tier 1 | C9: LMS time-to-competence + adoption | D9: 46143 | E9: =IFERROR(IF(B9="Insufficient data","n/a",IF(DATEDIF(D9,'Engagement Metadata'!$D$19,"m")<=INDEX(Ref!$B$41:$B$61,MATCH("C5",Ref!$A$41:$A$61,0)),"High",IF(DATEDIF(D9,'Engagement Metadata'!$D$19,"m")<=INDEX(Ref!$C$41:$C$61,MATCH("C5",Ref!$A$41:$A$61,0)),"Medium","Low"))),"-") -> High
A10: M1 - Engagement & confidence | B10: Tier 1 | C10: Culture Amp engagement composite | D10: 46147 | E10: =IFERROR(IF(B10="Insufficient data","n/a",IF(DATEDIF(D10,'Engagement Metadata'!$D$19,"m")<=INDEX(Ref!$B$41:$B$61,MATCH("M1",Ref!$A$41:$A$61,0)),"High",IF(DATEDIF(D10,'Engagement Metadata'!$D$19,"m")<=INDEX(Ref!$C$41:$C$61,MATCH("M1",Ref!$A$41:$A$61,0)),"Medium","Low"))),"-") -> High
A11: M2 - Psychological safety | B11: Tier 3 | C11: MI-2 module | D11: 46152 | E11: =IFERROR(IF(B11="Insufficient data","n/a",IF(DATEDIF(D11,'Engagement Metadata'!$D$19,"m")<=INDEX(Ref!$B$41:$B$61,MATCH("M2",Ref!$A$41:$A$61,0)),"High",IF(DATEDIF(D11,'Engagement Metadata'!$D$19,"m")<=INDEX(Ref!$C$41:$C$61,MATCH("M2",Ref!$A$41:$A$61,0)),"Medium","Low"))),"-") -> High
A12: M3 - Autonomous motivation | B12: Tier 3 | C12: MI-3 module | D12: 46152 | E12: =IFERROR(IF(B12="Insufficient data","n/a",IF(DATEDIF(D12,'Engagement Metadata'!$D$19,"m")<=INDEX(Ref!$B$41:$B$61,MATCH("M3",Ref!$A$41:$A$61,0)),"High",IF(DATEDIF(D12,'Engagement Metadata'!$D$19,"m")<=INDEX(Ref!$C$41:$C$61,MATCH("M3",Ref!$A$41:$A$61,0)),"Medium","Low"))),"-") -> High
A13: M4 - Purpose alignment | B13: Tier 3 | C13: MI-4 module | D13: 46152 | E13: =IFERROR(IF(B13="Insufficient data","n/a",IF(DATEDIF(D13,'Engagement Metadata'!$D$19,"m")<=INDEX(Ref!$B$41:$B$61,MATCH("M4",Ref!$A$41:$A$61,0)),"High",IF(DATEDIF(D13,'Engagement Metadata'!$D$19,"m")<=INDEX(Ref!$C$41:$C$61,MATCH("M4",Ref!$A$41:$A$61,0)),"Medium","Low"))),"-") -> High
A14: TW1 - Pay equity (trip-wire) | B14: Tier 3 | C14: TW item | D14: 46152 | E14: =IFERROR(IF(B14="Insufficient data","n/a",IF(DATEDIF(D14,'Engagement Metadata'!$D$19,"m")<=INDEX(Ref!$B$41:$B$61,MATCH("TW1",Ref!$A$41:$A$61,0)),"High",IF(DATEDIF(D14,'Engagement Metadata'!$D$19,"m")<=INDEX(Ref!$C$41:$C$61,MATCH("TW1",Ref!$A$41:$A$61,0)),"Medium","Low"))),"-") -> High
A15: TW2 - Fairness (trip-wire) | B15: Tier 3 | C15: TW item | D15: 46152 | E15: =IFERROR(IF(B15="Insufficient data","n/a",IF(DATEDIF(D15,'Engagement Metadata'!$D$19,"m")<=INDEX(Ref!$B$41:$B$61,MATCH("TW2",Ref!$A$41:$A$61,0)),"High",IF(DATEDIF(D15,'Engagement Metadata'!$D$19,"m")<=INDEX(Ref!$C$41:$C$61,MATCH("TW2",Ref!$A$41:$A$61,0)),"Medium","Low"))),"-") -> High
A16: TW3 - Basic conditions (trip-wire) | B16: Tier 3 | C16: TW item | D16: 46152 | E16: =IFERROR(IF(B16="Insufficient data","n/a",IF(DATEDIF(D16,'Engagement Metadata'!$D$19,"m")<=INDEX(Ref!$B$41:$B$61,MATCH("TW3",Ref!$A$41:$A$61,0)),"High",IF(DATEDIF(D16,'Engagement Metadata'!$D$19,"m")<=INDEX(Ref!$C$41:$C$61,MATCH("TW3",Ref!$A$41:$A$61,0)),"Medium","Low"))),"-") -> High | F16: Fires critical finding in sample
A17: O1 - Clarity & decision rights | B17: Tier 3 | C17: OI-Clarity audit + survey | D17: 46152 | E17: =IFERROR(IF(B17="Insufficient data","n/a",IF(DATEDIF(D17,'Engagement Metadata'!$D$19,"m")<=INDEX(Ref!$B$41:$B$61,MATCH("O1",Ref!$A$41:$A$61,0)),"High",IF(DATEDIF(D17,'Engagement Metadata'!$D$19,"m")<=INDEX(Ref!$C$41:$C$61,MATCH("O1",Ref!$A$41:$A$61,0)),"Medium","Low"))),"-") -> High | F17: Structural + perception
A18: O2 - Tools & information | B18: Tier 3 | C18: OI-2 audit + survey | D18: 46152 | E18: =IFERROR(IF(B18="Insufficient data","n/a",IF(DATEDIF(D18,'Engagement Metadata'!$D$19,"m")<=INDEX(Ref!$B$41:$B$61,MATCH("O2",Ref!$A$41:$A$61,0)),"High",IF(DATEDIF(D18,'Engagement Metadata'!$D$19,"m")<=INDEX(Ref!$C$41:$C$61,MATCH("O2",Ref!$A$41:$A$61,0)),"Medium","Low"))),"-") -> High | F18: Structural + perception
A19: O3 - Process & workflow | B19: Tier 3 | C19: OI-3 audit + survey | D19: 46152 | E19: =IFERROR(IF(B19="Insufficient data","n/a",IF(DATEDIF(D19,'Engagement Metadata'!$D$19,"m")<=INDEX(Ref!$B$41:$B$61,MATCH("O3",Ref!$A$41:$A$61,0)),"High",IF(DATEDIF(D19,'Engagement Metadata'!$D$19,"m")<=INDEX(Ref!$C$41:$C$61,MATCH("O3",Ref!$A$41:$A$61,0)),"Medium","Low"))),"-") -> High | F19: Structural + perception
A20: O4 - Resource adequacy | B20: Tier 3 | C20: OI-4 survey + capacity analysis | D20: 46152 | E20: =IFERROR(IF(B20="Insufficient data","n/a",IF(DATEDIF(D20,'Engagement Metadata'!$D$19,"m")<=INDEX(Ref!$B$41:$B$61,MATCH("O4",Ref!$A$41:$A$61,0)),"High",IF(DATEDIF(D20,'Engagement Metadata'!$D$19,"m")<=INDEX(Ref!$C$41:$C$61,MATCH("O4",Ref!$A$41:$A$61,0)),"Medium","Low"))),"-") -> High
A21: O5 - Leadership enablement | B21: Tier 3 | C21: OI-5 survey | D21: 46152 | E21: =IFERROR(IF(B21="Insufficient data","n/a",IF(DATEDIF(D21,'Engagement Metadata'!$D$19,"m")<=INDEX(Ref!$B$41:$B$61,MATCH("O5",Ref!$A$41:$A$61,0)),"High",IF(DATEDIF(D21,'Engagement Metadata'!$D$19,"m")<=INDEX(Ref!$C$41:$C$61,MATCH("O5",Ref!$A$41:$A$61,0)),"Medium","Low"))),"-") -> High | F21: Per-team, FTE-weighted
A22: S1 - Skill complementarity | B22: Tier 1 | C22: Reuses C1 skills data | D22: 46127 | E22: =IFERROR(IF(B22="Insufficient data","n/a",IF(DATEDIF(D22,'Engagement Metadata'!$D$19,"m")<=INDEX(Ref!$B$41:$B$61,MATCH("S1",Ref!$A$41:$A$61,0)),"High",IF(DATEDIF(D22,'Engagement Metadata'!$D$19,"m")<=INDEX(Ref!$C$41:$C$61,MATCH("S1",Ref!$A$41:$A$61,0)),"Medium","Low"))),"-") -> High | F22: Analytical protocol
A23: S2 - Collaboration friction | B23: Tier 1 | C23: Workplace Analytics + TSI-2 | D23: 46152 | E23: =IFERROR(IF(B23="Insufficient data","n/a",IF(DATEDIF(D23,'Engagement Metadata'!$D$19,"m")<=INDEX(Ref!$B$41:$B$61,MATCH("S2",Ref!$A$41:$A$61,0)),"High",IF(DATEDIF(D23,'Engagement Metadata'!$D$19,"m")<=INDEX(Ref!$C$41:$C$61,MATCH("S2",Ref!$A$41:$A$61,0)),"Medium","Low"))),"-") -> High | F23: Telemetry + perception
A24: S3 - Conflict health | B24: Tier 3 | C24: TSI-3 survey | D24: 46152 | E24: =IFERROR(IF(B24="Insufficient data","n/a",IF(DATEDIF(D24,'Engagement Metadata'!$D$19,"m")<=INDEX(Ref!$B$41:$B$61,MATCH("S3",Ref!$A$41:$A$61,0)),"High",IF(DATEDIF(D24,'Engagement Metadata'!$D$19,"m")<=INDEX(Ref!$C$41:$C$61,MATCH("S3",Ref!$A$41:$A$61,0)),"Medium","Low"))),"-") -> High
A25: DLP - Decision Latency Protocol | B25: Tier 3 | C25: DLP (PerformanceVP) | D25: 46157 | E25: =IFERROR(IF(B25="Insufficient data","n/a",IF(DATEDIF(D25,'Engagement Metadata'!$D$19,"m")<=INDEX(Ref!$B$41:$B$61,MATCH("DLP",Ref!$A$41:$A$61,0)),"High",IF(DATEDIF(D25,'Engagement Metadata'!$D$19,"m")<=INDEX(Ref!$C$41:$C$61,MATCH("DLP",Ref!$A$41:$A$61,0)),"Medium","Low"))),"-") -> High | F25: Reported alongside O

Sheet Capability Inputs
A1: Capability Inputs (C1–C5)
A2: C = weighted mean of C1–C5 (weights on Composite Scoring tab). Active route follows the Tier Assignment selector.
A4: C1 - Skill (Type B counts → workbook computes coverage; Tier 3 = M-C1-MGR finished score)
A5: Tier 1/2 route - one row per role family (apply Tier-2 provider adjustment to 'Confirmed' before entry)
A6: Role family | B6: FTE | C6: Skills required (per person) | D6: Confirmed proficiencies (adjusted) | E6: Coverage ratio | F6: Family C1 score | G6: _FTEvalid | H6: _contrib
A7: Customer Service Reps | B7: 50 | C7: 10 | D7: 380 | E7: =IFERROR(MIN(D7/(B7*C7),1),"") -> 0.76 | F7: =IFERROR(E7*100,"") -> 76 | G7: =IF(AND(ISNUMBER(B7),ISNUMBER(C7),ISNUMBER(D7),C7>0),B7,0) -> 50 | H7: =IF(G7>0,MIN(D7/(B7*C7),1)*100*B7,0) -> 3800
A8: Team Leaders | B8: 10 | C8: 12 | D8: 92 | E8: =IFERROR(MIN(D8/(B8*C8),1),"") -> 0.76666667 | F8: =IFERROR(E8*100,"") -> 76.666667 | G8: =IF(AND(ISNUMBER(B8),ISNUMBER(C8),ISNUMBER(D8),C8>0),B8,0) -> 10 | H8: =IF(G8>0,MIN(D8/(B8*C8),1)*100*B8,0) -> 766.66667
E9: =IFERROR(MIN(D9/(B9*C9),1),"") | F9: =IFERROR(E9*100,"") | G9: =IF(AND(ISNUMBER(B9),ISNUMBER(C9),ISNUMBER(D9),C9>0),B9,0) -> 0 | H9: =IF(G9>0,MIN(D9/(B9*C9),1)*100*B9,0) -> 0
A10: Median unit tenure (months) - experience moderator | D10: 22
A11: Tenure moderator | D11: =IF(ISNUMBER(D10),IF(D10<18,0.95,IF(D10>96,1.05,1)),1) -> 1
A12: C1 score (Tier 1/2) | D12: =IF(SUM(G7:G9)=0,"",SUM(H7:H9)/SUM(G7:G9)*D11) -> 76.111111
A13: Tier 3 route - M-C1-MGR module score (Type C, finished 0–100)
A15: C1 sub-dimension score | D15: =IF('Tier Assignment'!$B$5="Tier 3",D13,IF('Tier Assignment'!$B$5="Insufficient data","",D12)) -> 76.111111
A17: C2 - Knowledge (Type B; criticality-weighted, coverage-adjusted)
A18: Knowledge domain | B18: Criticality (1–3) | C18: Mean domain score (0–100) | D18: Coverage % | E18: Cov-adj score | F18: _critvalid | G18: _weighted
A19: Product & service knowledge | B19: 3 | C19: 84 | D19: 0.92 | E19: =IFERROR(C19*D19,"") -> 77.28 | F19: =IF(AND(ISNUMBER(B19),ISNUMBER(C19),ISNUMBER(D19)),B19,0) -> 3 | G19: =IF(F19>0,C19*D19*B19,0) -> 231.84
A20: Regulatory / compliance | B20: 2 | C20: 82 | D20: 0.88 | E20: =IFERROR(C20*D20,"") -> 72.16 | F20: =IF(AND(ISNUMBER(B20),ISNUMBER(C20),ISNUMBER(D20)),B20,0) -> 2 | G20: =IF(F20>0,C20*D20*B20,0) -> 144.32
A21: Systems & procedures | B21: 2 | C21: 78 | D21: 0.9 | E21: =IFERROR(C21*D21,"") -> 70.2 | F21: =IF(AND(ISNUMBER(B21),ISNUMBER(C21),ISNUMBER(D21)),B21,0) -> 2 | G21: =IF(F21>0,C21*D21*B21,0) -> 140.4
E22: =IFERROR(C22*D22,"") -> 0 | F22: =IF(AND(ISNUMBER(B22),ISNUMBER(C22),ISNUMBER(D22)),B22,0) -> 0 | G22: =IF(F22>0,C22*D22*B22,0) -> 0
A23: Critical-domain coverage check (need ≥1 criticality-3 at ≥60%) | D23: =IF(SUMPRODUCT(--(B19:B22=3),--(D19:D22>=0.6))>=1,"OK","INSUFFICIENT COVERAGE") -> OK
A24: C2 sub-dimension score | D24: =IF(SUM(F19:F22)=0,"",SUM(G19:G22)/SUM(F19:F22)) -> 73.794286
A26: C3 - Talent density (Type B; enter calibrated band counts - Tier-2 cap-exceptional adjustment applied before entry)
A27: Band | B27: Count | C27: Band weight | D27: Band %
A28: 5 - Exceptional | B28: 6 | C28: 100 | D28: =IFERROR(B28/SUM($B$28:$B$32),"") -> 0.1
A29: 4 - Exceeding | B29: 18 | C29: 80 | D29: =IFERROR(B29/SUM($B$28:$B$32),"") -> 0.3
A30: 3 - Meeting | B30: 29 | C30: 60 | D30: =IFERROR(B30/SUM($B$28:$B$32),"") -> 0.48333333
A31: 2 - Developing | B31: 6 | C31: 35 | D31: =IFERROR(B31/SUM($B$28:$B$32),"") -> 0.1
A32: 1 - Underperforming | B32: 1 | C32: 0 | D32: =IFERROR(B32/SUM($B$28:$B$32),"") -> 0.016666667
A33: C3 sub-dimension score | D33: =IF(SUM(B28:B32)=0,"",SUMPRODUCT(B28:B32,C28:C32)/SUM(B28:B32)) -> 66.5
A35: C4 - Collective Intelligence (Type A; CII 15 items → Clarity/Trust/Flow). Reverse items: CII-05, 10, 15
A36: Item | B36: Raw mean (1–5) | C36: Adjusted | D36: Sub-construct
A37: CII-01 | B37: 3.9 | C37: =IF(ISNUMBER(B37),B37,"") -> 3.9
A38: CII-02 | B38: 3.8 | C38: =IF(ISNUMBER(B38),B38,"") -> 3.8
A39: CII-03 | B39: 4 | C39: =IF(ISNUMBER(B39),B39,"") -> 4
A40: CII-04 | B40: 3.8 | C40: =IF(ISNUMBER(B40),B40,"") -> 3.8
A41: CII-05 | B41: 2.15 | C41: =IF(ISNUMBER(B41),6-B41,"") -> 3.85
A42: CII-06 | B42: 3.8 | C42: =IF(ISNUMBER(B42),B42,"") -> 3.8
A43: CII-07 | B43: 3.9 | C43: =IF(ISNUMBER(B43),B43,"") -> 3.9
A44: CII-08 | B44: 3.7 | C44: =IF(ISNUMBER(B44),B44,"") -> 3.7
A45: CII-09 | B45: 3.85 | C45: =IF(ISNUMBER(B45),B45,"") -> 3.85
...

Sheet Motivation Inputs
A1: Motivation Inputs (M1–M4 + trip-wires)
A2: M = weighted mean of M1–M4. Trip-wires are independent critical-finding overlays - NOT weighted into M.
A4: M1 - Engagement & confidence (Tier 1/2 = platform composite Type C; Tier 3 = MI-1 survey Type A, MI1-04 reverse)
A5: Tier 1/2 - platform engagement composite (0–100, Type C) | D5: 72
A6: Tier 3 - MI-1 module (8 items)
A7: Item | B7: Raw mean (1–5) | C7: Adjusted
A8: MI1-01 | B8: 3.9 | C8: =IF(ISNUMBER(B8),B8,"") -> 3.9
A9: MI1-02 | B9: 3.8 | C9: =IF(ISNUMBER(B9),B9,"") -> 3.8
A10: MI1-03 | B10: 4 | C10: =IF(ISNUMBER(B10),B10,"") -> 4
A11: MI1-04 | B11: 2.1 | C11: =IF(ISNUMBER(B11),6-B11,"") -> 3.9
A12: MI1-05 | B12: 3.85 | C12: =IF(ISNUMBER(B12),B12,"") -> 3.85
A13: MI1-06 | B13: 3.9 | C13: =IF(ISNUMBER(B13),B13,"") -> 3.9
A14: MI1-07 | B14: 3.8 | C14: =IF(ISNUMBER(B14),B14,"") -> 3.8
A15: MI1-08 | B15: 4 | C15: =IF(ISNUMBER(B15),B15,"") -> 4
A16: Response rate % | B16: 0.78
A17: M1 score (Tier 3) | D17: =IF(COUNT(C8:C15)=0,"",(AVERAGE(C8:C15)-1)*25) -> 72.34375
A19: M1 sub-dimension score | D19: =IF('Tier Assignment'!$B$10="Insufficient data","",IF('Tier Assignment'!$B$10="Tier 3",D17,D5)) -> 72
A21: M2 - Psychological safety (Type A; MI-2 5 items, MI2-05 reverse)
A22: Item | B22: Raw mean (1–5) | C22: Adjusted
A23: MI2-01 | B23: 4 | C23: =IF(ISNUMBER(B23),B23,"") -> 4
A24: MI2-02 | B24: 3.9 | C24: =IF(ISNUMBER(B24),B24,"") -> 3.9
A25: MI2-03 | B25: 4.1 | C25: =IF(ISNUMBER(B25),B25,"") -> 4.1
A26: MI2-04 | B26: 4 | C26: =IF(ISNUMBER(B26),B26,"") -> 4
A27: MI2-05 | B27: 2 | C27: =IF(ISNUMBER(B27),6-B27,"") -> 4
A28: Response rate % | B28: 0.78
A29: M2 sub-dimension score | D29: =IF(COUNT(C23:C27)=0,"",(AVERAGE(C23:C27)-1)*25) -> 75
A31: M3 - Autonomous motivation (Type A; MI-3 5 items, MI3-04 reverse)
A32: Item | B32: Raw mean (1–5) | C32: Adjusted
A33: MI3-01 | B33: 3.7 | C33: =IF(ISNUMBER(B33),B33,"") -> 3.7
A34: MI3-02 | B34: 3.6 | C34: =IF(ISNUMBER(B34),B34,"") -> 3.6
A35: MI3-03 | B35: 3.5 | C35: =IF(ISNUMBER(B35),B35,"") -> 3.5
A36: MI3-04 | B36: 2.3 | C36: =IF(ISNUMBER(B36),6-B36,"") -> 3.7
A37: MI3-05 | B37: 3.9 | C37: =IF(ISNUMBER(B37),B37,"") -> 3.9
A38: Response rate % | B38: 0.76
A39: M3 sub-dimension score | D39: =IF(COUNT(C33:C37)=0,"",(AVERAGE(C33:C37)-1)*25) -> 67
A41: M4 - Purpose alignment (Type A; MI-4 4 items, MI4-04 reverse)
A42: Item | B42: Raw mean (1–5) | C42: Adjusted
A43: MI4-01 | B43: 3.5 | C43: =IF(ISNUMBER(B43),B43,"") -> 3.5
A44: MI4-02 | B44: 3.4 | C44: =IF(ISNUMBER(B44),B44,"") -> 3.4
A45: MI4-03 | B45: 3.3 | C45: =IF(ISNUMBER(B45),B45,"") -> 3.3
...

Sheet Opportunity Inputs
A1: Opportunity Inputs (O1–O5)
A2: O1–O3 are two-layer composites: structural (Type C module + analyst doc-review) + perception (Type A survey), with a >15-point gap rule. O4 blends capacity + perception (no gap). O5 is per-team, FTE-weighted.
A4: O1 - Clarity & decision rights (structural 0.40·M-O1-LT + 0.30·role-arch + 0.30·M-O1-CASCADE)
A5: M-O1-LT decision-rights score (Type C) | D5: 62
A6: Role-architecture doc-review score (Type C) | D6: 60
A7: M-O1-CASCADE score (Type C) | D7: 65
A8: O1 structural | D8: =IFERROR(0.4*D5+0.3*D6+0.3*D7,"") -> 62.3
A9: Perception - OI1 (8 items; reverse OI1-03, OI1-06)
A10: Item | B10: Raw mean (1–5) | C10: Adjusted
A11: OI1-01 | B11: 3.5 | C11: =IF(ISNUMBER(B11),B11,"") -> 3.5
A12: OI1-02 | B12: 3.4 | C12: =IF(ISNUMBER(B12),B12,"") -> 3.4
A13: OI1-03 | B13: 2.6 | C13: =IF(ISNUMBER(B13),6-B13,"") -> 3.4
A14: OI1-04 | B14: 3.4 | C14: =IF(ISNUMBER(B14),B14,"") -> 3.4
A15: OI1-05 | B15: 3.3 | C15: =IF(ISNUMBER(B15),B15,"") -> 3.3
A16: OI1-06 | B16: 2.6 | C16: =IF(ISNUMBER(B16),6-B16,"") -> 3.4
A17: OI1-07 | B17: 3.4 | C17: =IF(ISNUMBER(B17),B17,"") -> 3.4
A18: OI1-08 | B18: 3.45 | C18: =IF(ISNUMBER(B18),B18,"") -> 3.45
A19: Response rate % | B19: 0.8
A20: O1 perception | D20: =IF(COUNT(C11:C18)=0,"",(AVERAGE(C11:C18)-1)*25) -> 60.15625
A21: O1 gap (structural − perception) | D21: =IFERROR(D8-D20,"") -> 2.14375
A22: O1 gap flag | D22: =IF(AND(ISNUMBER(D21),ABS(D21)>15),"GAP - report separately","")
A23: O1 sub-dimension score | D23: =IFERROR((D8+D20)/2,"") -> 61.228125
A25: O2 - Tools & information (structural 0.35·tool-inv + 0.40·M-O2-IA + 0.25·integration)
A26: Tool-inventory doc-review score (Type C) | D26: 80
A27: M-O2-IA information-access score (Type C) | D27: 70
A28: Integration doc-review score (Type C) | D28: 70
A29: O2 structural | D29: =IFERROR(0.35*D26+0.4*D27+0.25*D28,"") -> 73.5
A30: Perception - OI2 (4 items; reverse OI2-04)
A31: Item | B31: Raw mean (1–5) | C31: Adjusted
A32: OI2-01 | B32: 3.7 | C32: =IF(ISNUMBER(B32),B32,"") -> 3.7
A33: OI2-02 | B33: 3.6 | C33: =IF(ISNUMBER(B33),B33,"") -> 3.6
A34: OI2-03 | B34: 3.5 | C34: =IF(ISNUMBER(B34),B34,"") -> 3.5
A35: OI2-04 | B35: 2.4 | C35: =IF(ISNUMBER(B35),6-B35,"") -> 3.6
A36: Response rate % | B36: 0.82
A37: O2 perception | D37: =IF(COUNT(C32:C35)=0,"",(AVERAGE(C32:C35)-1)*25) -> 65
A38: O2 gap (structural − perception) | D38: =IFERROR(D29-D37,"") -> 8.5
A39: O2 gap flag | D39: =IF(AND(ISNUMBER(D38),ABS(D38)>15),"GAP - report separately","")
A40: O2 sub-dimension score | D40: =IFERROR((D29+D37)/2,"") -> 69.25
A42: O3 - Process & workflow (structural = M-O3-PF; single component)
A43: M-O3-PF process-friction score (Type C) | D43: 60
...

Sheet Synergy Inputs
A1: Synergy Inputs (S1–S3)
A2: S_internal = 0.30·S1 + 0.40·S2 + 0.30·S3 (computed on Composite Scoring tab). S2 telemetry is converted in-workbook via the band rules.
A4: S1 - Skill complementarity (S1 = 0.40·breadth + 0.35·depth + 0.25·distribution)
A5: Coverage breadth (0–100, Type C) | D5: 90
A6: Coverage depth (0–100, Type C) | D6: 85
A7: Distribution score (0–100, Type C) | D7: 80
A8: S1 sub-dimension score | D8: =IFERROR(0.4*D5+0.35*D6+0.25*D7,"") -> 85.75
A10: S2 - Collaboration friction (telemetry band-converted + TSI-2 perception; 0.5/0.5 where both exist)
A11: Telemetry indicator | B11: Raw value | C11: Converted (0–100)
A12: Meeting hours/week per IC | B12: 18 | C12: =IF(NOT(ISNUMBER(B12)),"",IF(B12<15,100,IF(B12<20,80,IF(B12<25,60,IF(B12<30,40,20))))) -> 80
A13: Meeting hours/week per manager | B13: 32 | C13: =IF(NOT(ISNUMBER(B13)),"",IF(B13<25,100,IF(B13<35,75,IF(B13<45,50,25)))) -> 75
A14: Fragmented time ratio (%) | B14: 0.72 | C14: =IF(NOT(ISNUMBER(B14)),"",IF(B14<0.5,100,IF(B14<0.65,75,IF(B14<0.8,50,25)))) -> 50
A15: After-hours collaboration (hrs/wk/person) | B15: 6 | C15: =IF(NOT(ISNUMBER(B15)),"",IF(B15<2,100,IF(B15<5,75,IF(B15<10,50,25)))) -> 50
A16: Behavioural composite | C16: =IF(COUNT(C12:C15)=0,"",AVERAGE(C12:C15)) -> 63.75
A17: Perception - TSI-2 (3 items; reverse TSI2-03)
A18: Item | B18: Raw mean (1–5) | C18: Adjusted
A19: TSI2-01 | B19: 2.8 | C19: =IF(ISNUMBER(B19),B19,"") -> 2.8
A20: TSI2-02 | B20: 2.8 | C20: =IF(ISNUMBER(B20),B20,"") -> 2.8
A21: TSI2-03 | B21: 3.2 | C21: =IF(ISNUMBER(B21),6-B21,"") -> 2.8
A22: Response rate % | B22: 0.82
A23: S2 perception | D23: =IF(COUNT(C19:C21)=0,"",(AVERAGE(C19:C21)-1)*25) -> 45
A24: S2 survey-behavioural gap | D24: =IF(AND(ISNUMBER(C16),ISNUMBER(D23)),C16-D23,"") -> 18.75
A25: S2 gap flag | D25: =IF(AND(ISNUMBER(D24),ABS(D24)>15),"GAP - diagnostic finding","") -> GAP - diagnostic finding
A26: S2 sub-dimension score | D26: =IF(AND(ISNUMBER(C16),ISNUMBER(D23)),0.5*C16+0.5*D23,IF(ISNUMBER(D23),D23,IF(ISNUMBER(C16),C16,""))) -> 54.375
A28: S3 - Conflict health (TSI-3 5 items; reverse TSI3-04, TSI3-05)
A29: Item | B29: Raw mean (1–5) | C29: Adjusted
A30: TSI3-01 | B30: 3.8 | C30: =IF(ISNUMBER(B30),B30,"") -> 3.8
A31: TSI3-02 | B31: 3.6 | C31: =IF(ISNUMBER(B31),B31,"") -> 3.6
A32: TSI3-03 | B32: 3.4 | C32: =IF(ISNUMBER(B32),B32,"") -> 3.4
A33: TSI3-04 | B33: 2.4 | C33: =IF(ISNUMBER(B33),6-B33,"") -> 3.6
A34: TSI3-05 | B34: 2.2 | C34: =IF(ISNUMBER(B34),6-B34,"") -> 3.8
A35: Response rate % | B35: 0.8
A36: S3 sub-dimension score | D36: =IF(COUNT(C30:C34)=0,"",(AVERAGE(C30:C34)-1)*25) -> 66
A37: False-consensus flag | D37: =IF(AND((B30-1)*25<60,(B31-1)*25<60,'Motivation Inputs'!$D$29>75),"FALSE CONSENSUS - suppressed disagreement","")

Sheet DLP
A1: Decision Latency Protocol (DLP)
A2: Per-decision latency converted to a 0-100 score against seeded class norms; DLS = 0.40 Operational + 0.35 Tactical + 0.25 Strategic. Reported alongside O, not in P.
A4: Decision ID | B4: Class | C4: Latency (days) | D4: Latency score | E4: Bottleneck flag | F4: Outcome quality | G4: Decision description
A5: OP-01 | B5: Operational | C5: 1 | D5: =IFERROR(IF(NOT(ISNUMBER(C5)),"",IF(C5<=INDEX(Ref!$B$35:$E$37,MATCH(B5,Ref!$A$35:$A$37,0),1),100,IF(C5<=INDEX(Ref!$B$35:$E$37,MATCH(B5,Ref!$A$35:$A$37,0),2),100-(C5-INDEX(Ref!$B$35:$E$37,MATCH(B5,Ref!$A$35:$A$37,0),1))/(INDEX(Ref!$B$35:$E$37,MATCH(B5,Ref!$A$35:$A$37,0),2)-INDEX(Ref!$B$35:$E$37,MATCH(B5,Ref!$A$35:$A$37,0),1))*25,IF(C5<=INDEX(Ref!$B$35:$E$37,MATCH(B5,Ref!$A$35:$A$37,0),3),75-(C5-INDEX(Ref!$B$35:$E$37,MATCH(B5,Ref!$A$35:$A$37,0),2))/(INDEX(Ref!$B$35:$E$37,MATCH(B5,Ref!$A$35:$A$37,0),3)-INDEX(Ref!$B$35:$E$37,MATCH(B5,Ref!$A$35:$A$37,0),2))*25,IF(C5<=INDEX(Ref!$B$35:$E$37,MATCH(B5,Ref!$A$35:$A$37,0),4),50-(C5-INDEX(Ref!$B$35:$E$37,MATCH(B5,Ref!$A$35:$A$37,0),3))/(INDEX(Ref!$B$35:$E$37,MATCH(B5,Ref!$A$35:$A$37,0),4)-INDEX(Ref!$B$35:$E$37,MATCH(B5,Ref!$A$35:$A$37,0),3))*25,MAX(0,25-(C5-INDEX(Ref!$B$35:$E$37,MATCH(B5,Ref!$A$35:$A$37,0),4))/INDEX(Ref!$B$35:$E$37,MATCH(B5,Ref!$A$35:$A$37,0),4)*25)))))),"") -> 100
A6: OP-02 | B6: Operational | C6: 1 | D6: =IFERROR(IF(NOT(ISNUMBER(C6)),"",IF(C6<=INDEX(Ref!$B$35:$E$37,MATCH(B6,Ref!$A$35:$A$37,0),1),100,IF(C6<=INDEX(Ref!$B$35:$E$37,MATCH(B6,Ref!$A$35:$A$37,0),2),100-(C6-INDEX(Ref!$B$35:$E$37,MATCH(B6,Ref!$A$35:$A$37,0),1))/(INDEX(Ref!$B$35:$E$37,MATCH(B6,Ref!$A$35:$A$37,0),2)-INDEX(Ref!$B$35:$E$37,MATCH(B6,Ref!$A$35:$A$37,0),1))*25,IF(C6<=INDEX(Ref!$B$35:$E$37,MATCH(B6,Ref!$A$35:$A$37,0),3),75-(C6-INDEX(Ref!$B$35:$E$37,MATCH(B6,Ref!$A$35:$A$37,0),2))/(INDEX(Ref!$B$35:$E$37,MATCH(B6,Ref!$A$35:$A$37,0),3)-INDEX(Ref!$B$35:$E$37,MATCH(B6,Ref!$A$35:$A$37,0),2))*25,IF(C6<=INDEX(Ref!$B$35:$E$37,MATCH(B6,Ref!$A$35:$A$37,0),4),50-(C6-INDEX(Ref!$B$35:$E$37,MATCH(B6,Ref!$A$35:$A$37,0),3))/(INDEX(Ref!$B$35:$E$37,MATCH(B6,Ref!$A$35:$A$37,0),4)-INDEX(Ref!$B$35:$E$37,MATCH(B6,Ref!$A$35:$A$37,0),3))*25,MAX(0,25-(C6-INDEX(Ref!$B$35:$E$37,MATCH(B6,Ref!$A$35:$A$37,0),4))/INDEX(Ref!$B$35:$E$37,MATCH(B6,Ref!$A$35:$A$37,0),4)*25)))))),"") -> 100
A7: OP-03 | B7: Operational | C7: 2 | D7: =IFERROR(IF(NOT(ISNUMBER(C7)),"",IF(C7<=INDEX(Ref!$B$35:$E$37,MATCH(B7,Ref!$A$35:$A$37,0),1),100,IF(C7<=INDEX(Ref!$B$35:$E$37,MATCH(B7,Ref!$A$35:$A$37,0),2),100-(C7-INDEX(Ref!$B$35:$E$37,MATCH(B7,Ref!$A$35:$A$37,0),1))/(INDEX(Ref!$B$35:$E$37,MATCH(B7,Ref!$A$35:$A$37,0),2)-INDEX(Ref!$B$35:$E$37,MATCH(B7,Ref!$A$35:$A$37,0),1))*25,IF(C7<=INDEX(Ref!$B$35:$E$37,MATCH(B7,Ref!$A$35:$A$37,0),3),75-(C7-INDEX(Ref!$B$35:$E$37,MATCH(B7,Ref!$A$35:$A$37,0),2))/(INDEX(Ref!$B$35:$E$37,MATCH(B7,Ref!$A$35:$A$37,0),3)-INDEX(Ref!$B$35:$E$37,MATCH(B7,Ref!$A$35:$A$37,0),2))*25,IF(C7<=INDEX(Ref!$B$35:$E$37,MATCH(B7,Ref!$A$35:$A$37,0),4),50-(C7-INDEX(Ref!$B$35:$E$37,MATCH(B7,Ref!$A$35:$A$37,0),3))/(INDEX(Ref!$B$35:$E$37,MATCH(B7,Ref!$A$35:$A$37,0),4)-INDEX(Ref!$B$35:$E$37,MATCH(B7,Ref!$A$35:$A$37,0),3))*25,MAX(0,25-(C7-INDEX(Ref!$B$35:$E$37,MATCH(B7,Ref!$A$35:$A$37,0),4))/INDEX(Ref!$B$35:$E$37,MATCH(B7,Ref!$A$35:$A$37,0),4)*25)))))),"") -> 87.5
A8: OP-04 | B8: Operational | C8: 2 | D8: =IFERROR(IF(NOT(ISNUMBER(C8)),"",IF(C8<=INDEX(Ref!$B$35:$E$37,MATCH(B8,Ref!$A$35:$A$37,0),1),100,IF(C8<=INDEX(Ref!$B$35:$E$37,MATCH(B8,Ref!$A$35:$A$37,0),2),100-(C8-INDEX(Ref!$B$35:$E$37,MATCH(B8,Ref!$A$35:$A$37,0),1))/(INDEX(Ref!$B$35:$E$37,MATCH(B8,Ref!$A$35:$A$37,0),2)-INDEX(Ref!$B$35:$E$37,MATCH(B8,Ref!$A$35:$A$37,0),1))*25,IF(C8<=INDEX(Ref!$B$35:$E$37,MATCH(B8,Ref!$A$35:$A$37,0),3),75-(C8-INDEX(Ref!$B$35:$E$37,MATCH(B8,Ref!$A$35:$A$37,0),2))/(INDEX(Ref!$B$35:$E$37,MATCH(B8,Ref!$A$35:$A$37,0),3)-INDEX(Ref!$B$35:$E$37,MATCH(B8,Ref!$A$35:$A$37,0),2))*25,IF(C8<=INDEX(Ref!$B$35:$E$37,MATCH(B8,Ref!$A$35:$A$37,0),4),50-(C8-INDEX(Ref!$B$35:$E$37,MATCH(B8,Ref!$A$35:$A$37,0),3))/(INDEX(Ref!$B$35:$E$37,MATCH(B8,Ref!$A$35:$A$37,0),4)-INDEX(Ref!$B$35:$E$37,MATCH(B8,Ref!$A$35:$A$37,0),3))*25,MAX(0,25-(C8-INDEX(Ref!$B$35:$E$37,MATCH(B8,Ref!$A$35:$A$37,0),4))/INDEX(Ref!$B$35:$E$37,MATCH(B8,Ref!$A$35:$A$37,0),4)*25)))))),"") -> 87.5
A9: OP-05 | B9: Operational | C9: 2 | D9: =IFERROR(IF(NOT(ISNUMBER(C9)),"",IF(C9<=INDEX(Ref!$B$35:$E$37,MATCH(B9,Ref!$A$35:$A$37,0),1),100,IF(C9<=INDEX(Ref!$B$35:$E$37,MATCH(B9,Ref!$A$35:$A$37,0),2),100-(C9-INDEX(Ref!$B$35:$E$37,MATCH(B9,Ref!$A$35:$A$37,0),1))/(INDEX(Ref!$B$35:$E$37,MATCH(B9,Ref!$A$35:$A$37,0),2)-INDEX(Ref!$B$35:$E$37,MATCH(B9,Ref!$A$35:$A$37,0),1))*25,IF(C9<=INDEX(Ref!$B$35:$E$37,MATCH(B9,Ref!$A$35:$A$37,0),3),75-(C9-INDEX(Ref!$B$35:$E$37,MATCH(B9,Ref!$A$35:$A$37,0),2))/(INDEX(Ref!$B$35:$E$37,MATCH(B9,Ref!$A$35:$A$37,0),3)-INDEX(Ref!$B$35:$E$37,MATCH(B9,Ref!$A$35:$A$37,0),2))*25,IF(C9<=INDEX(Ref!$B$35:$E$37,MATCH(B9,Ref!$A$35:$A$37,0),4),50-(C9-INDEX(Ref!$B$35:$E$37,MATCH(B9,Ref!$A$35:$A$37,0),3))/(INDEX(Ref!$B$35:$E$37,MATCH(B9,Ref!$A$35:$A$37,0),4)-INDEX(Ref!$B$35:$E$37,MATCH(B9,Ref!$A$35:$A$37,0),3))*25,MAX(0,25-(C9-INDEX(Ref!$B$35:$E$37,MATCH(B9,Ref!$A$35:$A$37,0),4))/INDEX(Ref!$B$35:$E$37,MATCH(B9,Ref!$A$35:$A$37,0),4)*25)))))),"") -> 87.5
A10: OP-06 | B10: Operational | C10: 3 | D10: =IFERROR(IF(NOT(ISNUMBER(C10)),"",IF(C10<=INDEX(Ref!$B$35:$E$37,MATCH(B10,Ref!$A$35:$A$37,0),1),100,IF(C10<=INDEX(Ref!$B$35:$E$37,MATCH(B10,Ref!$A$35:$A$37,0),2),100-(C10-INDEX(Ref!$B$35:$E$37,MATCH(B10,Ref!$A$35:$A$37,0),1))/(INDEX(Ref!$B$35:$E$37,MATCH(B10,Ref!$A$35:$A$37,0),2)-INDEX(Ref!$B$35:$E$37,MATCH(B10,Ref!$A$35:$A$37,0),1))*25,IF(C10<=INDEX(Ref!$B$35:$E$37,MATCH(B10,Ref!$A$35:$A$37,0),3),75-(C10-INDEX(Ref!$B$35:$E$37,MATCH(B10,Ref!$A$35:$A$37,0),2))/(INDEX(Ref!$B$35:$E$37,MATCH(B10,Ref!$A$35:$A$37,0),3)-INDEX(Ref!$B$35:$E$37,MATCH(B10,Ref!$A$35:$A$37,0),2))*25,IF(C10<=INDEX(Ref!$B$35:$E$37,MATCH(B10,Ref!$A$35:$A$37,0),4),50-(C10-INDEX(Ref!$B$35:$E$37,MATCH(B10,Ref!$A$35:$A$37,0),3))/(INDEX(Ref!$B$35:$E$37,MATCH(B10,Ref!$A$35:$A$37,0),4)-INDEX(Ref!$B$35:$E$37,MATCH(B10,Ref!$A$35:$A$37,0),3))*25,MAX(0,25-(C10-INDEX(Ref!$B$35:$E$37,MATCH(B10,Ref!$A$35:$A$37,0),4))/INDEX(Ref!$B$35:$E$37,MATCH(B10,Ref!$A$35:$A$37,0),4)*25)))))),"") -> 75
A11: OP-07 | B11: Operational | C11: 3 | D11: =IFERROR(IF(NOT(ISNUMBER(C11)),"",IF(C11<=INDEX(Ref!$B$35:$E$37,MATCH(B11,Ref!$A$35:$A$37,0),1),100,IF(C11<=INDEX(Ref!$B$35:$E$37,MATCH(B11,Ref!$A$35:$A$37,0),2),100-(C11-INDEX(Ref!$B$35:$E$37,MATCH(B11,Ref!$A$35:$A$37,0),1))/(INDEX(Ref!$B$35:$E$37,MATCH(B11,Ref!$A$35:$A$37,0),2)-INDEX(Ref!$B$35:$E$37,MATCH(B11,Ref!$A$35:$A$37,0),1))*25,IF(C11<=INDEX(Ref!$B$35:$E$37,MATCH(B11,Ref!$A$35:$A$37,0),3),75-(C11-INDEX(Ref!$B$35:$E$37,MATCH(B11,Ref!$A$35:$A$37,0),2))/(INDEX(Ref!$B$35:$E$37,MATCH(B11,Ref!$A$35:$A$37,0),3)-INDEX(Ref!$B$35:$E$37,MATCH(B11,Ref!$A$35:$A$37,0),2))*25,IF(C11<=INDEX(Ref!$B$35:$E$37,MATCH(B11,Ref!$A$35:$A$37,0),4),50-(C11-INDEX(Ref!$B$35:$E$37,MATCH(B11,Ref!$A$35:$A$37,0),3))/(INDEX(Ref!$B$35:$E$37,MATCH(B11,Ref!$A$35:$A$37,0),4)-INDEX(Ref!$B$35:$E$37,MATCH(B11,Ref!$A$35:$A$37,0),3))*25,MAX(0,25-(C11-INDEX(Ref!$B$35:$E$37,MATCH(B11,Ref!$A$35:$A$37,0),4))/INDEX(Ref!$B$35:$E$37,MATCH(B11,Ref!$A$35:$A$37,0),4)*25)))))),"") -> 75
A12: OP-08 | B12: Operational | C12: 3 | D12: =IFERROR(IF(NOT(ISNUMBER(C12)),"",IF(C12<=INDEX(Ref!$B$35:$E$37,MATCH(B12,Ref!$A$35:$A$37,0),1),100,IF(C12<=INDEX(Ref!$B$35:$E$37,MATCH(B12,Ref!$A$35:$A$37,0),2),100-(C12-INDEX(Ref!$B$35:$E$37,MATCH(B12,Ref!$A$35:$A$37,0),1))/(INDEX(Ref!$B$35:$E$37,MATCH(B12,Ref!$A$35:$A$37,0),2)-INDEX(Ref!$B$35:$E$37,MATCH(B12,Ref!$A$35:$A$37,0),1))*25,IF(C12<=INDEX(Ref!$B$35:$E$37,MATCH(B12,Ref!$A$35:$A$37,0),3),75-(C12-INDEX(Ref!$B$35:$E$37,MATCH(B12,Ref!$A$35:$A$37,0),2))/(INDEX(Ref!$B$35:$E$37,MATCH(B12,Ref!$A$35:$A$37,0),3)-INDEX(Ref!$B$35:$E$37,MATCH(B12,Ref!$A$35:$A$37,0),2))*25,IF(C12<=INDEX(Ref!$B$35:$E$37,MATCH(B12,Ref!$A$35:$A$37,0),4),50-(C12-INDEX(Ref!$B$35:$E$37,MATCH(B12,Ref!$A$35:$A$37,0),3))/(INDEX(Ref!$B$35:$E$37,MATCH(B12,Ref!$A$35:$A$37,0),4)-INDEX(Ref!$B$35:$E$37,MATCH(B12,Ref!$A$35:$A$37,0),3))*25,MAX(0,25-(C12-INDEX(Ref!$B$35:$E$37,MATCH(B12,Ref!$A$35:$A$37,0),4))/INDEX(Ref!$B$35:$E$37,MATCH(B12,Ref!$A$35:$A$37,0),4)*25)))))),"") -> 75
A13: OP-09 | B13: Operational | C13: 4 | D13: =IFERROR(IF(NOT(ISNUMBER(C13)),"",IF(C13<=INDEX(Ref!$B$35:$E$37,MATCH(B13,Ref!$A$35:$A$37,0),1),100,IF(C13<=INDEX(Ref!$B$35:$E$37,MATCH(B13,Ref!$A$35:$A$37,0),2),100-(C13-INDEX(Ref!$B$35:$E$37,MATCH(B13,Ref!$A$35:$A$37,0),1))/(INDEX(Ref!$B$35:$E$37,MATCH(B13,Ref!$A$35:$A$37,0),2)-INDEX(Ref!$B$35:$E$37,MATCH(B13,Ref!$A$35:$A$37,0),1))*25,IF(C13<=INDEX(Ref!$B$35:$E$37,MATCH(B13,Ref!$A$35:$A$37,0),3),75-(C13-INDEX(Ref!$B$35:$E$37,MATCH(B13,Ref!$A$35:$A$37,0),2))/(INDEX(Ref!$B$35:$E$37,MATCH(B13,Ref!$A$35:$A$37,0),3)-INDEX(Ref!$B$35:$E$37,MATCH(B13,Ref!$A$35:$A$37,0),2))*25,IF(C13<=INDEX(Ref!$B$35:$E$37,MATCH(B13,Ref!$A$35:$A$37,0),4),50-(C13-INDEX(Ref!$B$35:$E$37,MATCH(B13,Ref!$A$35:$A$37,0),3))/(INDEX(Ref!$B$35:$E$37,MATCH(B13,Ref!$A$35:$A$37,0),4)-INDEX(Ref!$B$35:$E$37,MATCH(B13,Ref!$A$35:$A$37,0),3))*25,MAX(0,25-(C13-INDEX(Ref!$B$35:$E$37,MATCH(B13,Ref!$A$35:$A$37,0),4))/INDEX(Ref!$B$35:$E$37,MATCH(B13,Ref!$A$35:$A$37,0),4)*25)))))),"") -> 68.75
A14: OP-10 | B14: Operational | C14: 5 | D14: =IFERROR(IF(NOT(ISNUMBER(C14)),"",IF(C14<=INDEX(Ref!$B$35:$E$37,MATCH(B14,Ref!$A$35:$A$37,0),1),100,IF(C14<=INDEX(Ref!$B$35:$E$37,MATCH(B14,Ref!$A$35:$A$37,0),2),100-(C14-INDEX(Ref!$B$35:$E$37,MATCH(B14,Ref!$A$35:$A$37,0),1))/(INDEX(Ref!$B$35:$E$37,MATCH(B14,Ref!$A$35:$A$37,0),2)-INDEX(Ref!$B$35:$E$37,MATCH(B14,Ref!$A$35:$A$37,0),1))*25,IF(C14<=INDEX(Ref!$B$35:$E$37,MATCH(B14,Ref!$A$35:$A$37,0),3),75-(C14-INDEX(Ref!$B$35:$E$37,MATCH(B14,Ref!$A$35:$A$37,0),2))/(INDEX(Ref!$B$35:$E$37,MATCH(B14,Ref!$A$35:$A$37,0),3)-INDEX(Ref!$B$35:$E$37,MATCH(B14,Ref!$A$35:$A$37,0),2))*25,IF(C14<=INDEX(Ref!$B$35:$E$37,MATCH(B14,Ref!$A$35:$A$37,0),4),50-(C14-INDEX(Ref!$B$35:$E$37,MATCH(B14,Ref!$A$35:$A$37,0),3))/(INDEX(Ref!$B$35:$E$37,MATCH(B14,Ref!$A$35:$A$37,0),4)-INDEX(Ref!$B$35:$E$37,MATCH(B14,Ref!$A$35:$A$37,0),3))*25,MAX(0,25-(C14-INDEX(Ref!$B$35:$E$37,MATCH(B14,Ref!$A$35:$A$37,0),4))/INDEX(Ref!$B$35:$E$37,MATCH(B14,Ref!$A$35:$A$37,0),4)*25)))))),"") -> 62.5
A15: OP-11 | B15: Operational | C15: 5 | D15: =IFERROR(IF(NOT(ISNUMBER(C15)),"",IF(C15<=INDEX(Ref!$B$35:$E$37,MATCH(B15,Ref!$A$35:$A$37,0),1),100,IF(C15<=INDEX(Ref!$B$35:$E$37,MATCH(B15,Ref!$A$35:$A$37,0),2),100-(C15-INDEX(Ref!$B$35:$E$37,MATCH(B15,Ref!$A$35:$A$37,0),1))/(INDEX(Ref!$B$35:$E$37,MATCH(B15,Ref!$A$35:$A$37,0),2)-INDEX(Ref!$B$35:$E$37,MATCH(B15,Ref!$A$35:$A$37,0),1))*25,IF(C15<=INDEX(Ref!$B$35:$E$37,MATCH(B15,Ref!$A$35:$A$37,0),3),75-(C15-INDEX(Ref!$B$35:$E$37,MATCH(B15,Ref!$A$35:$A$37,0),2))/(INDEX(Ref!$B$35:$E$37,MATCH(B15,Ref!$A$35:$A$37,0),3)-INDEX(Ref!$B$35:$E$37,MATCH(B15,Ref!$A$35:$A$37,0),2))*25,IF(C15<=INDEX(Ref!$B$35:$E$37,MATCH(B15,Ref!$A$35:$A$37,0),4),50-(C15-INDEX(Ref!$B$35:$E$37,MATCH(B15,Ref!$A$35:$A$37,0),3))/(INDEX(Ref!$B$35:$E$37,MATCH(B15,Ref!$A$35:$A$37,0),4)-INDEX(Ref!$B$35:$E$37,MATCH(B15,Ref!$A$35:$A$37,0),3))*25,MAX(0,25-(C15-INDEX(Ref!$B$35:$E$37,MATCH(B15,Ref!$A$35:$A$37,0),4))/INDEX(Ref!$B$35:$E$37,MATCH(B15,Ref!$A$35:$A$37,0),4)*25)))))),"") -> 62.5
A16: OP-12 | B16: Operational | C16: 6 | D16: =IFERROR(IF(NOT(ISNUMBER(C16)),"",IF(C16<=INDEX(Ref!$B$35:$E$37,MATCH(B16,Ref!$A$35:$A$37,0),1),100,IF(C16<=INDEX(Ref!$B$35:$E$37,MATCH(B16,Ref!$A$35:$A$37,0),2),100-(C16-INDEX(Ref!$B$35:$E$37,MATCH(B16,Ref!$A$35:$A$37,0),1))/(INDEX(Ref!$B$35:$E$37,MATCH(B16,Ref!$A$35:$A$37,0),2)-INDEX(Ref!$B$35:$E$37,MATCH(B16,Ref!$A$35:$A$37,0),1))*25,IF(C16<=INDEX(Ref!$B$35:$E$37,MATCH(B16,Ref!$A$35:$A$37,0),3),75-(C16-INDEX(Ref!$B$35:$E$37,MATCH(B16,Ref!$A$35:$A$37,0),2))/(INDEX(Ref!$B$35:$E$37,MATCH(B16,Ref!$A$35:$A$37,0),3)-INDEX(Ref!$B$35:$E$37,MATCH(B16,Ref!$A$35:$A$37,0),2))*25,IF(C16<=INDEX(Ref!$B$35:$E$37,MATCH(B16,Ref!$A$35:$A$37,0),4),50-(C16-INDEX(Ref!$B$35:$E$37,MATCH(B16,Ref!$A$35:$A$37,0),3))/(INDEX(Ref!$B$35:$E$37,MATCH(B16,Ref!$A$35:$A$37,0),4)-INDEX(Ref!$B$35:$E$37,MATCH(B16,Ref!$A$35:$A$37,0),3))*25,MAX(0,25-(C16-INDEX(Ref!$B$35:$E$37,MATCH(B16,Ref!$A$35:$A$37,0),4))/INDEX(Ref!$B$35:$E$37,MATCH(B16,Ref!$A$35:$A$37,0),4)*25)))))),"") -> 56.25
... A47: ST-08 | B47: Strategic | C47: 200 | D47: =IFERROR(IF(NOT(ISNUMBER(C47)),"",IF(C47<=INDEX(Ref!$B$35:$E$37,MATCH(B47,Ref!$A$35:$A$37,0),1),100,IF(C47<=INDEX(Ref!$B$35:$E$37,MATCH(B47,Ref!$A$35:$A$37,0),2),100-(C47-INDEX(Ref!$B$35:$E$37,MATCH(B47,Ref!$A$35:$A$37,0),1))/(INDEX(Ref!$B$35:$E$37,MATCH(B47,Ref!$A$35:$A$37,0),2)-INDEX(Ref!$B$35:$E$37,MATCH(B47,Ref!$A$35:$A$37,0),1))*25,IF(C47<=INDEX(Ref!$B$35:$E$37,MATCH(B47,Ref!$A$35:$A$37,0),3),75-(C47-INDEX(Ref!$B$35:$E$37,MATCH(B47,Ref!$A$35:$A$37,0),2))/(INDEX(Ref!$B$35:$E$37,MATCH(B47,Ref!$A$35:$A$37,0),3)-INDEX(Ref!$B$35:$E$37,MATCH(B47,Ref!$A$35:$A$37,0),2))*25,IF(C47<=INDEX(Ref!$B$35:$E$37,MATCH(B47,Ref!$A$35:$A$37,0),4),50-(C47-INDEX(Ref!$B$35:$E$37,MATCH(B47,Ref!$A$35:$A$37,0),3))/(INDEX(Ref!$B$35:$E$37,MATCH(B47,Ref!$A$35:$A$37,0),4)-INDEX(Ref!$B$35:$E$37,MATCH(B47,Ref!$A$35:$A$37,0),3))*25,MAX(0,25-(C47-INDEX(Ref!$B$35:$E$37,MATCH(B47,Ref!$A$35:$A$37,0),4))/INDEX(Ref!$B$35:$E$37,MATCH(B47,Ref!$A$35:$A$37,0),4)*25)))))),"") -> 16.666667
A49: Operational DLS | B49: =IFERROR(AVERAGEIF(B5:B47,"Operational",D5:D47),"") -> 62.723214 | C49: Sample | D49: =COUNTIF(B5:B47,"Operational") -> 20 | E49: =IF(D49<10,"BELOW MIN (10)","")
A50: Tactical DLS | B50: =IFERROR(AVERAGEIF(B5:B47,"Tactical",D5:D47),"") -> 62.637363 | C50: Sample | D50: =COUNTIF(B5:B47,"Tactical") -> 15 | E50: =IF(D50<5,"BELOW MIN (5)","")
A51: Strategic DLS | B51: =IFERROR(AVERAGEIF(B5:B47,"Strategic",D5:D47),"") -> 55.208333 | C51: Sample | D51: =COUNTIF(B5:B47,"Strategic") -> 8 | E51: =IF(D51<3,"BELOW MIN (3)","")
A52: Overall DLS | B52: =IFERROR(Ref!$B$9*B49+Ref!$B$10*B50+Ref!$B$11*B51,"") -> 60.814446

Sheet Behavioural Triangulators
A1: Behavioural Triangulators
A2: Each triangulator is converted to 0-100 against benchmark norms BEFORE entry (Type C). The behavioural composite is compared to the M1 survey score; it does not average into M1.
A4: Triangulator | B4: Raw value (reference) | C4: Converted score (0-100)
A5: Voluntary turnover (12-mo rolling) | B5: 14% | C5: 68
A6: Unplanned absence (days/FTE) | B6: 5.2 | C6: 60
A7: eNPS | B7: 22 | C7: 68
A8: Goal achievement rate | B8: 78% | C8: 68
A9: Behavioural composite | C9: =IF(COUNT(C5:C8)=0,"",AVERAGE(C5:C8)) -> 66
A10: M1 survey-behavioural gap | C10: =IFERROR('Motivation Inputs'!$D$19-C9,"") -> 6
A11: M1 gap flag | C11: =IF(AND(ISNUMBER(C10),ABS(C10)>15),"GAP - key finding","")

Sheet Sector Classification
A1: Sector Classification (metadata for internal comparison)
A2: Metadata only; not in the equation. Mirrors Engagement Metadata. No external benchmark is applied.
A4: Client | C4: ='Engagement Metadata'!$D$11 -> Northwind Mutual
A5: Unit | C5: ='Engagement Metadata'!$D$12 -> Member Services
A6: Unit FTE | C6: ='Engagement Metadata'!$D$13 -> 60
A7: ANZSIC division | C7: ='Engagement Metadata'!$D$14 -> K - Financial and Insurance Services
A8: Sub-sector | C8: ='Engagement Metadata'!$D$15 -> Health insurance
A9: Size band | C9: ='Engagement Metadata'!$D$16 -> 200–1,000 FTE
A10: Unit type | C10: ='Engagement Metadata'!$D$17 -> Customer-facing service
A11: Engagement date | C11: ='Engagement Metadata'!$D$19 -> 46174
A13: Internal comparison set
A14: Comparison percentile (where cell n>=15) | C14: No comparison applied - set not yet large enough

Sheet Composite Scoring
A1: Composite Scoring
A2: Calculated. Component weights follow the selected archetype and are normalised by the sum of active weights (this also handles any 'insufficient data' sub-dimension). P = S x (C^0.35 x M^0.40 x O^0.25).
A4: Sub-dim | B4: Score | C4: Weight | D4: Avail | E4: Wt x Score | F4: Wt x Avail
A5: Capability | H5: Capability | I5: C1 | J5: C1 - Skill | K5: =B6 -> 76.111111 | L5: =IF(SUM(F6:F10)=0,0,C6*D6/SUM(F6:F10)) -> 0.35 | M5: =B27 -> 72.973032 | N5: =Ref!$B$4 -> 0.35 | O5: =IF(ISNUMBER(K5),Ref!$E$5*MAX(0,Ref!$E$4-K5),"") -> 2.6666667 | P5: =IF(ISNUMBER(K5),B32*((1+L5*O5/M5)^N5-1),"") -> 0.32237994 | Q5: =IF(ISNUMBER(K5),1/(1+EXP((K5-AVERAGE($K$5:$K$18))/Ref!$E$6)),"") -> 0.24410008 | R5: =IF(ISNUMBER(K5),P5*Q5,"") -> 0.07869297 | S5: =IF(ISNUMBER(R5),R5-ROW()/1000000,"") -> 0.07868797
A6: C1 | B6: ='Capability Inputs'!$D$15 -> 76.111111 | C6: =INDEX(Ref!$C$15:$H$31,MATCH("C1",Ref!$A$15:$A$31,0),MATCH('Engagement Metadata'!$D$18,Ref!$C$14:$H$14,0)) -> 0.35 | D6: =IF(ISNUMBER(B6),1,0) -> 1 | E6: =IF(ISNUMBER(B6),B6*C6,0) -> 26.638889 | F6: =C6*D6 -> 0.35 | H6: Capability | I6: C2 | J6: C2 - Knowledge | K6: =B7 -> 73.794286 | L6: =IF(SUM(F6:F10)=0,0,C7*D7/SUM(F6:F10)) -> 0.15 | M6: =B27 -> 72.973032 | N6: =Ref!$B$4 -> 0.35 | O6: =IF(ISNUMBER(K6),Ref!$E$5*MAX(0,Ref!$E$4-K6),"") -> 3.3617143 | P6: =IF(ISNUMBER(K6),B32*((1+L6*O6/M6)^N6-1),"") -> 0.17450462 | Q6: =IF(ISNUMBER(K6),1/(1+EXP((K6-AVERAGE($K$5:$K$18))/Ref!$E$6)),"") -> 0.30138159 | R6: =IF(ISNUMBER(K6),P6*Q6,"") -> 0.05259248 | S6: =IF(ISNUMBER(R6),R6-ROW()/1000000,"") -> 0.05258648
A7: C2 | B7: ='Capability Inputs'!$D$24 -> 73.794286 | C7: =INDEX(Ref!$C$15:$H$31,MATCH("C2",Ref!$A$15:$A$31,0),MATCH('Engagement Metadata'!$D$18,Ref!$C$14:$H$14,0)) -> 0.15 | D7: =IF(ISNUMBER(B7),1,0) -> 1 | E7: =IF(ISNUMBER(B7),B7*C7,0) -> 11.069143 | F7: =C7*D7 -> 0.15 | H7: Capability | I7: C3 | J7: C3 - Talent density | K7: =B8 -> 66.5 | L7: =IF(SUM(F6:F10)=0,0,C8*D8/SUM(F6:F10)) -> 0.2 | M7: =B27 -> 72.973032 | N7: =Ref!$B$4 -> 0.35 | O7: =IF(ISNUMBER(K7),Ref!$E$5*MAX(0,Ref!$E$4-K7),"") -> 5.55 | P7: =IF(ISNUMBER(K7),B32*((1+L7*O7/M7)^N7-1),"") -> 0.38310353 | Q7: =IF(ISNUMBER(K7),1/(1+EXP((K7-AVERAGE($K$5:$K$18))/Ref!$E$6)),"") -> 0.51775709 | R7: =IF(ISNUMBER(K7),P7*Q7,"") -> 0.19835457 | S7: =IF(ISNUMBER(R7),R7-ROW()/1000000,"") -> 0.19834757
A8: C3 | B8: ='Capability Inputs'!$D$33 -> 66.5 | C8: =INDEX(Ref!$C$15:$H$31,MATCH("C3",Ref!$A$15:$A$31,0),MATCH('Engagement Metadata'!$D$18,Ref!$C$14:$H$14,0)) -> 0.2 | D8: =IF(ISNUMBER(B8),1,0) -> 1 | E8: =IF(ISNUMBER(B8),B8*C8,0) -> 13.3 | F8: =C8*D8 -> 0.2 | H8: Capability | I8: C4 | J8: C4 - Collective intelligence | K8: =B9 -> 70.325 | L8: =IF(SUM(F6:F10)=0,0,C9*D9/SUM(F6:F10)) -> 0.2 | M8: =B27 -> 72.973032 | N8: =Ref!$B$4 -> 0.35 | O8: =IF(ISNUMBER(K8),Ref!$E$5*MAX(0,Ref!$E$4-K8),"") -> 4.4025 | P8: =IF(ISNUMBER(K8),B32*((1+L8*O8/M8)^N8-1),"") -> 0.30420182 | Q8: =IF(ISNUMBER(K8),1/(1+EXP((K8-AVERAGE($K$5:$K$18))/Ref!$E$6)),"") -> 0.39961566 | R8: =IF(ISNUMBER(K8),P8*Q8,"") -> 0.12156381 | S8: =IF(ISNUMBER(R8),R8-ROW()/1000000,"") -> 0.12155581
A9: C4 | B9: ='Capability Inputs'!$D$56 -> 70.325 | C9: =INDEX(Ref!$C$15:$H$31,MATCH("C4",Ref!$A$15:$A$31,0),MATCH('Engagement Metadata'!$D$18,Ref!$C$14:$H$14,0)) -> 0.2 | D9: =IF(ISNUMBER(B9),1,0) -> 1 | E9: =IF(ISNUMBER(B9),B9*C9,0) -> 14.065 | F9: =C9*D9 -> 0.2 | H9: Capability | I9: C5 | J9: C5 - Learning velocity | K9: =B10 -> 79 | L9: =IF(SUM(F6:F10)=0,0,C10*D10/SUM(F6:F10)) -> 0.1 | M9: =B27 -> 72.973032 | N9: =Ref!$B$4 -> 0.35 | O9: =IF(ISNUMBER(K9),Ref!$E$5*MAX(0,Ref!$E$4-K9),"") -> 1.8 | P9: =IF(ISNUMBER(K9),B32*((1+L9*O9/M9)^N9-1),"") -> 0.062380994 | Q9: =IF(ISNUMBER(K9),1/(1+EXP((K9-AVERAGE($K$5:$K$18))/Ref!$E$6)),"") -> 0.18370542 | R9: =IF(ISNUMBER(K9),P9*Q9,"") -> 0.011459727 | S9: =IF(ISNUMBER(R9),R9-ROW()/1000000,"") -> 0.011450727
A10: C5 | B10: ='Capability Inputs'!$D$63 -> 79 | C10: =INDEX(Ref!$C$15:$H$31,MATCH("C5",Ref!$A$15:$A$31,0),MATCH('Engagement Metadata'!$D$18,Ref!$C$14:$H$14,0)) -> 0.1 | D10: =IF(ISNUMBER(B10),1,0) -> 1 | E10: =IF(ISNUMBER(B10),B10*C10,0) -> 7.9 | F10: =C10*D10 -> 0.1 | H10: Motivation | I10: M1 | J10: M1 - Engagement & confidence | K10: =B12 -> 72 | L10: =IF(SUM(F12:F15)=0,0,C12*D12/SUM(F12:F15)) -> 0.5 | M10: =B28 -> 70.05 | N10: =Ref!$B$5 -> 0.4 | O10: =IF(ISNUMBER(K10),Ref!$E$5*MAX(0,Ref!$E$4-K10),"") -> 3.9 | P10: =IF(ISNUMBER(K10),B32*((1+L10*O10/M10)^N10-1),"") -> 0.79858226 | Q10: =IF(ISNUMBER(K10),1/(1+EXP((K10-AVERAGE($K$5:$K$18))/Ref!$E$6)),"") -> 0.35059115 | R10: =IF(ISNUMBER(K10),P10*Q10,"") -> 0.27997587 | S10: =IF(ISNUMBER(R10),R10-ROW()/1000000,"") -> 0.27996587
A11: Motivation | H11: Motivation | I11: M2 | J11: M2 - Psychological safety | K11: =B13 -> 75 | L11: =IF(SUM(F12:F15)=0,0,C13*D13/SUM(F12:F15)) -> 0.2 | M11: =B28 -> 70.05 | N11: =Ref!$B$5 -> 0.4 | O11: =IF(ISNUMBER(K11),Ref!$E$5*MAX(0,Ref!$E$4-K11),"") -> 3 | P11: =IF(ISNUMBER(K11),B32*((1+L11*O11/M11)^N11-1),"") -> 0.24712276 | Q11: =IF(ISNUMBER(K11),1/(1+EXP((K11-AVERAGE($K$5:$K$18))/Ref!$E$6)),"") -> 0.2706274 | R11: =IF(ISNUMBER(K11),P11*Q11,"") -> 0.066878189 | S11: =IF(ISNUMBER(R11),R11-ROW()/1000000,"") -> 0.066867189
A12: M1 | B12: ='Motivation Inputs'!$D$19 -> 72 | C12: =INDEX(Ref!$C$15:$H$31,MATCH("M1",Ref!$A$15:$A$31,0),MATCH('Engagement Metadata'!$D$18,Ref!$C$14:$H$14,0)) -> 0.5 | D12: =IF(ISNUMBER(B12),1,0) -> 1 | E12: =IF(ISNUMBER(B12),B12*C12,0) -> 36 | F12: =C12*D12 -> 0.5 | H12: Motivation | I12: M3 | J12: M3 - Autonomous motivation | K12: =B14 -> 67 | L12: =IF(SUM(F12:F15)=0,0,C14*D14/SUM(F12:F15)) -> 0.15 | M12: =B28 -> 70.05 | N12: =Ref!$B$5 -> 0.4 | O12: =IF(ISNUMBER(K12),Ref!$E$5*MAX(0,Ref!$E$4-K12),"") -> 5.4 | P12: =IF(ISNUMBER(K12),B32*((1+L12*O12/M12)^N12-1),"") -> 0.33331812 | Q12: =IF(ISNUMBER(K12),1/(1+EXP((K12-AVERAGE($K$5:$K$18))/Ref!$E$6)),"") -> 0.50213954 | R12: =IF(ISNUMBER(K12),P12*Q12,"") -> 0.16737221 | S12: =IF(ISNUMBER(R12),R12-ROW()/1000000,"") -> 0.16736021
A13: M2 | B13: ='Motivation Inputs'!$D$29 -> 75 | C13: =INDEX(Ref!$C$15:$H$31,MATCH("M2",Ref!$A$15:$A$31,0),MATCH('Engagement Metadata'!$D$18,Ref!$C$14:$H$14,0)) -> 0.2 | D13: =IF(ISNUMBER(B13),1,0) -> 1 | E13: =IF(ISNUMBER(B13),B13*C13,0) -> 15 | F13: =C13*D13 -> 0.2 | H13: Motivation | I13: M4 | J13: M4 - Purpose alignment | K13: =B15 -> 60 | L13: =IF(SUM(F12:F15)=0,0,C15*D15/SUM(F12:F15)) -> 0.15 | M13: =B28 -> 70.05 | N13: =Ref!$B$5 -> 0.4 | O13: =IF(ISNUMBER(K13),Ref!$E$5*MAX(0,Ref!$E$4-K13),"") -> 7.5 | P13: =IF(ISNUMBER(K13),B32*((1+L13*O13/M13)^N13-1),"") -> 0.46232425 | Q13: =IF(ISNUMBER(K13),1/(1+EXP((K13-AVERAGE($K$5:$K$18))/Ref!$E$6)),"") -> 0.70755903 | R13: =IF(ISNUMBER(K13),P13*Q13,"") -> 0.3271217 | S13: =IF(ISNUMBER(R13),R13-ROW()/1000000,"") -> 0.3271087
A14: M3 | B14: ='Motivation Inputs'!$D$39 -> 67 | C14: =INDEX(Ref!$C$15:$H$31,MATCH("M3",Ref!$A$15:$A$31,0),MATCH('Engagement Metadata'!$D$18,Ref!$C$14:$H$14,0)) -> 0.15 | D14: =IF(ISNUMBER(B14),1,0) -> 1 | E14: =IF(ISNUMBER(B14),B14*C14,0) -> 10.05 | F14: =C14*D14 -> 0.15 | H14: Opportunity | I14: O1 | J14: O1 - Clarity & decision rights | K14: =B17 -> 61.228125 | L14: =IF(SUM(F17:F21)=0,0,C17*D17/SUM(F17:F21)) -> 0.3 | M14: =B29 -> 61.380938 | N14: =Ref!$B$6 -> 0.25 | O14: =IF(ISNUMBER(K14),Ref!$E$5*MAX(0,Ref!$E$4-K14),"") -> 7.1315625 | P14: =IF(ISNUMBER(K14),B32*((1+L14*O14/M14)^N14-1),"") -> 0.6220633 | Q14: =IF(ISNUMBER(K14),1/(1+EXP((K14-AVERAGE($K$5:$K$18))/Ref!$E$6)),"") -> 0.67481462 | R14: =IF(ISNUMBER(K14),P14*Q14,"") -> 0.41977741 | S14: =IF(ISNUMBER(R14),R14-ROW()/1000000,"") -> 0.41976341
A15: M4 | B15: ='Motivation Inputs'!$D$48 -> 60 | C15: =INDEX(Ref!$C$15:$H$31,MATCH("M4",Ref!$A$15:$A$31,0),MATCH('Engagement Metadata'!$D$18,Ref!$C$14:$H$14,0)) -> 0.15 | D15: =IF(ISNUMBER(B15),1,0) -> 1 | E15: =IF(ISNUMBER(B15),B15*C15,0) -> 9 | F15: =C15*D15 -> 0.15 | H15: Opportunity | I15: O2 | J15: O2 - Tools & information | K15: =B18 -> 69.25 | L15: =IF(SUM(F17:F21)=0,0,C18*D18/SUM(F17:F21)) -> 0.25 | M15: =B29 -> 61.380938 | N15: =Ref!$B$6 -> 0.25 | O15: =IF(ISNUMBER(K15),Ref!$E$5*MAX(0,Ref!$E$4-K15),"") -> 4.725 | P15: =IF(ISNUMBER(K15),B32*((1+L15*O15/M15)^N15-1),"") -> 0.34542972 | Q15: =IF(ISNUMBER(K15),1/(1+EXP((K15-AVERAGE($K$5:$K$18))/Ref!$E$6)),"") -> 0.43224639 | R15: =IF(ISNUMBER(K15),P15*Q15,"") -> 0.14931075 | S15: =IF(ISNUMBER(R15),R15-ROW()/1000000,"") -> 0.14929575
A16: Opportunity | H16: Opportunity | I16: O3 | J16: O3 - Process & workflow | K16: =B19 -> 55.25 | L16: =IF(SUM(F17:F21)=0,0,C19*D19/SUM(F17:F21)) -> 0.2 | M16: =B29 -> 61.380938 | N16: =Ref!$B$6 -> 0.25 | O16: =IF(ISNUMBER(K16),Ref!$E$5*MAX(0,Ref!$E$4-K16),"") -> 8.925 | P16: =IF(ISNUMBER(K16),B32*((1+L16*O16/M16)^N16-1),"") -> 0.52009682 | Q16: =IF(ISNUMBER(K16),1/(1+EXP((K16-AVERAGE($K$5:$K$18))/Ref!$E$6)),"") -> 0.81416566 | R16: =IF(ISNUMBER(K16),P16*Q16,"") -> 0.42344497 | S16: =IF(ISNUMBER(R16),R16-ROW()/1000000,"") -> 0.42342897
A17: O1 | B17: ='Opportunity Inputs'!$D$23 -> 61.228125 | C17: =INDEX(Ref!$C$15:$H$31,MATCH("O1",Ref!$A$15:$A$31,0),MATCH('Engagement Metadata'!$D$18,Ref!$C$14:$H$14,0)) -> 0.3 | D17: =IF(ISNUMBER(B17),1,0) -> 1 | E17: =IF(ISNUMBER(B17),B17*C17,0) -> 18.368437 | F17: =C17*D17 -> 0.3 | H17: Opportunity | I17: O4 | J17: O4 - Resource adequacy | K17: =B20 -> 47.5 | L17: =IF(SUM(F17:F21)=0,0,C20*D20/SUM(F17:F21)) -> 0.1 | M17: =B29 -> 61.380938 | N17: =Ref!$B$6 -> 0.25 | O17: =IF(ISNUMBER(K17),Ref!$E$5*MAX(0,Ref!$E$4-K17),"") -> 11.25 | P17: =IF(ISNUMBER(K17),B32*((1+L17*O17/M17)^N17-1),"") -> 0.32909211 | Q17: =IF(ISNUMBER(K17),1/(1+EXP((K17-AVERAGE($K$5:$K$18))/Ref!$E$6)),"") -> 0.92027272 | R17: =IF(ISNUMBER(K17),P17*Q17,"") -> 0.30285449 | S17: =IF(ISNUMBER(R17),R17-ROW()/1000000,"") -> 0.30283749
A18: O2 | B18: ='Opportunity Inputs'!$D$40 -> 69.25 | C18: =INDEX(Ref!$C$15:$H$31,MATCH("O2",Ref!$A$15:$A$31,0),MATCH('Engagement Metadata'!$D$18,Ref!$C$14:$H$14,0)) -> 0.25 | D18: =IF(ISNUMBER(B18),1,0) -> 1 | E18: =IF(ISNUMBER(B18),B18*C18,0) -> 17.3125 | F18: =C18*D18 -> 0.25 | H18: Opportunity | I18: O5 | J18: O5 - Leadership enablement | K18: =B21 -> 66 | L18: =IF(SUM(F17:F21)=0,0,C21*D21/SUM(F17:F21)) -> 0.15 | M18: =B29 -> 61.380938 | N18: =Ref!$B$6 -> 0.25 | O18: =IF(ISNUMBER(K18),Ref!$E$5*MAX(0,Ref!$E$4-K18),"") -> 5.7 | P18: =IF(ISNUMBER(K18),B32*((1+L18*O18/M18)^N18-1),"") -> 0.25051771 | Q18: =IF(ISNUMBER(K18),1/(1+EXP((K18-AVERAGE($K$5:$K$18))/Ref!$E$6)),"") -> 0.53334001 | R18: =IF(ISNUMBER(K18),P18*Q18,"") -> 0.13361112 | S18: =IF(ISNUMBER(R18),R18-ROW()/1000000,"") -> 0.13359312
A19: O3 | B19: ='Opportunity Inputs'!$D$56 -> 55.25 | C19: =INDEX(Ref!$C$15:$H$31,MATCH("O3",Ref!$A$15:$A$31,0),MATCH('Engagement Metadata'!$D$18,Ref!$C$14:$H$14,0)) -> 0.2 | D19: =IF(ISNUMBER(B19),1,0) -> 1 | E19: =IF(ISNUMBER(B19),B19*C19,0) -> 11.05 | F19: =C19*D19 -> 0.2
A20: O4 | B20: ='Opportunity Inputs'!$D$67 -> 47.5 | C20: =INDEX(Ref!$C$15:$H$31,MATCH("O4",Ref!$A$15:$A$31,0),MATCH('Engagement Metadata'!$D$18,Ref!$C$14:$H$14,0)) -> 0.1 | D20: =IF(ISNUMBER(B20),1,0) -> 1 | E20: =IF(ISNUMBER(B20),B20*C20,0) -> 4.75 | F20: =C20*D20 -> 0.1
A21: O5 | B21: ='Opportunity Inputs'!$D$75 -> 66 | C21: =INDEX(Ref!$C$15:$H$31,MATCH("O5",Ref!$A$15:$A$31,0),MATCH('Engagement Metadata'!$D$18,Ref!$C$14:$H$14,0)) -> 0.15 | D21: =IF(ISNUMBER(B21),1,0) -> 1 | E21: =IF(ISNUMBER(B21),B21*C21,0) -> 9.9 | F21: =C21*D21 -> 0.15
A22: Synergy
A23: S1 | B23: ='Synergy Inputs'!$D$8 -> 85.75 | C23: =INDEX(Ref!$C$15:$H$31,MATCH("S1",Ref!$A$15:$A$31,0),MATCH('Engagement Metadata'!$D$18,Ref!$C$14:$H$14,0)) -> 0.3 | D23: =IF(ISNUMBER(B23),1,0) -> 1 | E23: =IF(ISNUMBER(B23),B23*C23,0) -> 25.725 | F23: =C23*D23 -> 0.3
A24: S2 | B24: ='Synergy Inputs'!$D$26 -> 54.375 | C24: =INDEX(Ref!$C$15:$H$31,MATCH("S2",Ref!$A$15:$A$31,0),MATCH('Engagement Metadata'!$D$18,Ref!$C$14:$H$14,0)) -> 0.4 | D24: =IF(ISNUMBER(B24),1,0) -> 1 | E24: =IF(ISNUMBER(B24),B24*C24,0) -> 21.75 | F24: =C24*D24 -> 0.4
A25: S3 | B25: ='Synergy Inputs'!$D$36 -> 66 | C25: =INDEX(Ref!$C$15:$H$31,MATCH("S3",Ref!$A$15:$A$31,0),MATCH('Engagement Metadata'!$D$18,Ref!$C$14:$H$14,0)) -> 0.3 | D25: =IF(ISNUMBER(B25),1,0) -> 1 | E25: =IF(ISNUMBER(B25),B25*C25,0) -> 19.8 | F25: =C25*D25 -> 0.3
A27: Capability (C) | B27: =IF(SUM(F6:F10)=0,"",SUM(E6:E10)/SUM(F6:F10)) -> 72.973032
A28: Motivation (M) | B28: =IF(SUM(F12:F15)=0,"",SUM(E12:E15)/SUM(F12:F15)) -> 70.05
A29: Opportunity (O) | B29: =IF(SUM(F17:F21)=0,"",SUM(E17:E21)/SUM(F17:F21)) -> 61.380938
A30: Synergy internal | B30: =IF(SUM(F23:F25)=0,50,SUM(E23:E25)/SUM(F23:F25)) -> 67.275
A31: Synergy coefficient (S) | B31: =MAX(Ref!$B$7,MIN(Ref!$B$7+Ref!$B$8,Ref!$B$7+(B30/100)*Ref!$B$8)) -> 1.051825
A32: P score | B32: =IF(AND(ISNUMBER(B27),ISNUMBER(B28),ISNUMBER(B29),ISNUMBER(B31)),B31*(B27^Ref!$B$4*B28^Ref!$B$5*B29^Ref!$B$6),"") -> 72.313929
A34: Binding constraints - top 6 by priority
A35: Rank | B35: Component | C35: Sub-dimension | D35: Raw score | E35: Realistic P gain | F35: Priority
A36: 1 | B36: =IFERROR(INDEX($H$5:$H$18,MATCH(LARGE($S$5:$S$18,1),$S$5:$S$18,0)),"") -> Opportunity | C36: =IFERROR(INDEX($J$5:$J$18,MATCH(LARGE($S$5:$S$18,1),$S$5:$S$18,0)),"") -> O3 - Process & workflow | D36: =IFERROR(INDEX($K$5:$K$18,MATCH(LARGE($S$5:$S$18,1),$S$5:$S$18,0)),"") -> 55.25 | E36: =IFERROR(INDEX($P$5:$P$18,MATCH(LARGE($S$5:$S$18,1),$S$5:$S$18,0)),"") -> 0.52009682 | F36: =IFERROR(INDEX($R$5:$R$18,MATCH(LARGE($S$5:$S$18,1),$S$5:$S$18,0)),"") -> 0.42344497
A37: 2 | B37: =IFERROR(INDEX($H$5:$H$18,MATCH(LARGE($S$5:$S$18,2),$S$5:$S$18,0)),"") -> Opportunity | C37: =IFERROR(INDEX($J$5:$J$18,MATCH(LARGE($S$5:$S$18,2),$S$5:$S$18,0)),"") -> O1 - Clarity & decision rights | D37: =IFERROR(INDEX($K$5:$K$18,MATCH(LARGE($S$5:$S$18,2),$S$5:$S$18,0)),"") -> 61.228125 | E37: =IFERROR(INDEX($P$5:$P$18,MATCH(LARGE($S$5:$S$18,2),$S$5:$S$18,0)),"") -> 0.6220633 | F37: =IFERROR(INDEX($R$5:$R$18,MATCH(LARGE($S$5:$S$18,2),$S$5:$S$18,0)),"") -> 0.41977741
A38: 3 | B38: =IFERROR(INDEX($H$5:$H$18,MATCH(LARGE($S$5:$S$18,3),$S$5:$S$18,0)),"") -> Motivation | C38: =IFERROR(INDEX($J$5:$J$18,MATCH(LARGE($S$5:$S$18,3),$S$5:$S$18,0)),"") -> M4 - Purpose alignment | D38: =IFERROR(INDEX($K$5:$K$18,MATCH(LARGE($S$5:$S$18,3),$S$5:$S$18,0)),"") -> 60 | E38: =IFERROR(INDEX($P$5:$P$18,MATCH(LARGE($S$5:$S$18,3),$S$5:$S$18,0)),"") -> 0.46232425 | F38: =IFERROR(INDEX($R$5:$R$18,MATCH(LARGE($S$5:$S$18,3),$S$5:$S$18,0)),"") -> 0.3271217
A39: 4 | B39: =IFERROR(INDEX($H$5:$H$18,MATCH(LARGE($S$5:$S$18,4),$S$5:$S$18,0)),"") -> Opportunity | C39: =IFERROR(INDEX($J$5:$J$18,MATCH(LARGE($S$5:$S$18,4),$S$5:$S$18,0)),"") -> O4 - Resource adequacy | D39: =IFERROR(INDEX($K$5:$K$18,MATCH(LARGE($S$5:$S$18,4),$S$5:$S$18,0)),"") -> 47.5 | E39: =IFERROR(INDEX($P$5:$P$18,MATCH(LARGE($S$5:$S$18,4),$S$5:$S$18,0)),"") -> 0.32909211 | F39: =IFERROR(INDEX($R$5:$R$18,MATCH(LARGE($S$5:$S$18,4),$S$5:$S$18,0)),"") -> 0.30285449
A40: 5 | B40: =IFERROR(INDEX($H$5:$H$18,MATCH(LARGE($S$5:$S$18,5),$S$5:$S$18,0)),"") -> Motivation | C40: =IFERROR(INDEX($J$5:$J$18,MATCH(LARGE($S$5:$S$18,5),$S$5:$S$18,0)),"") -> M1 - Engagement & confidence | D40: =IFERROR(INDEX($K$5:$K$18,MATCH(LARGE($S$5:$S$18,5),$S$5:$S$18,0)),"") -> 72 | E40: =IFERROR(INDEX($P$5:$P$18,MATCH(LARGE($S$5:$S$18,5),$S$5:$S$18,0)),"") -> 0.79858226 | F40: =IFERROR(INDEX($R$5:$R$18,MATCH(LARGE($S$5:$S$18,5),$S$5:$S$18,0)),"") -> 0.27997587
A41: 6 | B41: =IFERROR(INDEX($H$5:$H$18,MATCH(LARGE($S$5:$S$18,6),$S$5:$S$18,0)),"") -> Capability | C41: =IFERROR(INDEX($J$5:$J$18,MATCH(LARGE($S$5:$S$18,6),$S$5:$S$18,0)),"") -> C3 - Talent density | D41: =IFERROR(INDEX($K$5:$K$18,MATCH(LARGE($S$5:$S$18,6),$S$5:$S$18,0)),"") -> 66.5 | E41: =IFERROR(INDEX($P$5:$P$18,MATCH(LARGE($S$5:$S$18,6),$S$5:$S$18,0)),"") -> 0.38310353 | F41: =IFERROR(INDEX($R$5:$R$18,MATCH(LARGE($S$5:$S$18,6),$S$5:$S$18,0)),"") -> 0.19835457
A42: Priority ranks each C/M/O sub-dimension by the realistic gain in P from a bounded, diminishing-returns improvement (rho x (S_cap - score)), weighted by how far the score sits below the unit's own average. Realistic P gain is the P-point gain itself; the ordering is by Priority, so a high-leverage strength can show a larger gain yet rank lower. Synergy is a coefficient, not a candidate; Decision Latency and the trip-wires are reported separately.
A44: Binding component | B44: =IF(AND(ISNUMBER(B27),ISNUMBER(B28),ISNUMBER(B29)),IF(B27<=B28,IF(B27<=B29,"Capability",IF(B28<=B29,"Motivation","Opportunity")),IF(B28<=B29,"Motivation","Opportunity")),"") -> Opportunity
...

Sheet Methodology Footer
A1: Methodology Footer
A2: Calculated. Auto-populates from the other tabs; the audit trail for the report.
A4: Engagement
A5: Client / Unit | C5: ='Engagement Metadata'!$D$11&" - "&'Engagement Metadata'!$D$12 -> Northwind Mutual - Member Services
A6: Unit FTE | C6: ='Engagement Metadata'!$D$13 -> 60
A7: Archetype applied | C7: ='Engagement Metadata'!$D$18 -> Default
A8: Engagement date | C8: ='Engagement Metadata'!$D$19 -> 46174
A9: Tier mix
A10: Tier 1 sub-dims | C10: =COUNTIF('Tier Assignment'!$B$5:$B$24,"Tier 1") -> 7
A11: Tier 2 sub-dims | C11: =COUNTIF('Tier Assignment'!$B$5:$B$24,"Tier 2") -> 0
A12: Tier 3 sub-dims | C12: =COUNTIF('Tier Assignment'!$B$5:$B$24,"Tier 3") -> 13
A13: Composite tier rating | C13: =IF(COUNTIF('Tier Assignment'!$B$5:$B$24,"Tier 3")>COUNTIF('Tier Assignment'!$B$5:$B$24,"Tier 1")+COUNTIF('Tier Assignment'!$B$5:$B$24,"Tier 2"),"Tier-3-dominant; methodology disclosed",IF(COUNTIF('Tier Assignment'!$B$5:$B$24,"Tier 1")>=COUNTIF('Tier Assignment'!$B$5:$B$24,"Tier 2")+COUNTIF('Tier Assignment'!$B$5:$B$24,"Tier 3"),"Tier-1 dominant","Mixed")) -> Tier-3-dominant; methodology disclosed
A14: Confidence
A15: Overall P confidence | C15: ='Composite Scoring'!$B$51 -> High
A16: Gap flags fired
A17: M1 survey-behavioural | C17: =IF('Behavioural Triangulators'!$C$11="","none",'Behavioural Triangulators'!$C$11) -> none
A18: False-consensus | C18: =IF('Synergy Inputs'!$D$37="","none",'Synergy Inputs'!$D$37) -> none
A19: S2 telemetry-perception | C19: =IF('Synergy Inputs'!$D$25="","none",'Synergy Inputs'!$D$25) -> GAP - diagnostic finding
A20: O1 audit-perception | C20: =IF('Opportunity Inputs'!$D$22="","none",'Opportunity Inputs'!$D$22) -> none
A21: O2 audit-perception | C21: =IF('Opportunity Inputs'!$D$39="","none",'Opportunity Inputs'!$D$39) -> none
A22: O3 audit-perception | C22: =IF('Opportunity Inputs'!$D$55="","none",'Opportunity Inputs'!$D$55) -> none
A23: Critical findings
A24: Trip-wire breaches | C24: =IF((IF('Motivation Inputs'!D52<>"","Pay equity trip-wire breached; ","")&IF('Motivation Inputs'!D53<>"","Fairness trip-wire breached; ","")&IF('Motivation Inputs'!D54<>"","Basic conditions trip-wire breached; ","")&IF(AND(ISNUMBER(DLP!B52),DLP!B52<50),"Decision latency critical (overall DLS below 50); ",""))="","No critical findings identified",LEFT((IF('Motivation Inputs'!D52<>"","Pay equity trip-wire breached; ","")&IF('Motivation Inputs'!D53<>"","Fairness trip-wire breached; ","")&IF('Motivation Inputs'!D54<>"","Basic conditions trip-wire breached; ","")&IF(AND(ISNUMBER(DLP!B52),DLP!B52<50),"Decision latency critical (overall DLS below 50); ","")),LEN((IF('Motivation Inputs'!D52<>"","Pay equity trip-wire breached; ","")&IF('Motivation Inputs'!D53<>"","Fairness trip-wire breached; ","")&IF('Motivation Inputs'!D54<>"","Basic conditions trip-wire breached; ","")&IF(AND(ISNUMBER(DLP!B52),DLP!B52<50),"Decision latency critical (overall DLS below 50); ","")))-2)) -> Basic conditions trip-wire breached
A25: Internal comparison | C25: ="No comparison applied - set not yet large enough" -> No comparison applied - set not yet large enough
A28: Response rates (per construct)
A29: C4 - Collective intelligence | C29: ='Capability Inputs'!B52 -> 0.78
A30: M1 - Engagement & confidence | C30: ='Motivation Inputs'!B16 -> 0.78
A31: M2 - Psychological safety | C31: ='Motivation Inputs'!B28 -> 0.78
A32: M3 - Autonomous motivation | C32: ='Motivation Inputs'!B38 -> 0.76
A33: M4 - Purpose alignment | C33: ='Motivation Inputs'!B47 -> 0.76
A34: O1 - Clarity & decision rights | C34: ='Opportunity Inputs'!B19 -> 0.8
A35: O2 - Tools & information | C35: ='Opportunity Inputs'!B36 -> 0.82
A36: O3 - Process & workflow | C36: ='Opportunity Inputs'!B52 -> 0.83
A37: O4 - Resource adequacy | C37: ='Opportunity Inputs'!B65 -> 0.8
A38: S2 - Collaboration friction | C38: ='Synergy Inputs'!B22 -> 0.82
A39: S3 - Conflict health | C39: ='Synergy Inputs'!B35 -> 0.8
A41: Exclusions summary | C41: =IF(COUNTIF('Tier Assignment'!B5:B25,"Insufficient data")=0,"No sub-dimensions suppressed; full weight set applied; no responses excluded beyond validity screening","Sub-dimensions suppressed for insufficient data: "&COUNTIF('Tier Assignment'!B5:B25,"Insufficient data")&" (weights reallocated proportionally; see Tier Assignment)") -> No sub-dimensions suppressed; full weight set applied; no responses excluded beyond validity screening
A43: Non-standard data definitions | C43: =IF('Analyst Evidence'!C13="","None recorded",'Analyst Evidence'!C13) -> None recorded

Sheet Report Data
A1: Report Data (paste-ready)
A2: Calculated. The hand-off contract for the Unit Report (Word) and Client Report (PowerPoint).
A4: Headline | D4: Band
A5: P score | C5: ='Composite Scoring'!$B$32 -> 72.313929 | D5: =IF(NOT(ISNUMBER(C5)),"Neutral",IF(C5>75,"Green",IF(C5>=50,"Amber","Red"))) -> Amber
A6: P confidence | C6: ='Composite Scoring'!$B$51 -> High
A7: Capability (C) | C7: ='Composite Scoring'!$B$27 -> 72.973032 | D7: =IF(NOT(ISNUMBER(C7)),"Neutral",IF(C7>75,"Green",IF(C7>=50,"Amber","Red"))) -> Amber
A8: Motivation (M) | C8: ='Composite Scoring'!$B$28 -> 70.05 | D8: =IF(NOT(ISNUMBER(C8)),"Neutral",IF(C8>75,"Green",IF(C8>=50,"Amber","Red"))) -> Amber
A9: Opportunity (O) | C9: ='Composite Scoring'!$B$29 -> 61.380938 | D9: =IF(NOT(ISNUMBER(C9)),"Neutral",IF(C9>75,"Green",IF(C9>=50,"Amber","Red"))) -> Amber
A10: Synergy (S) | C10: ='Composite Scoring'!$B$31 -> 1.051825
A11: Binding constraint | C11: ='Composite Scoring'!$B$45 -> O3 - Process & workflow is the binding constraint, the highest-priority place a realistic improvement would lift P; Opportunity is the lowest-scoring force
