Workbook

Sheet 1 Setup & Keys
A1: Survey Processing and Scoring Workbook
A2: One workbook per unit. Intake layer between Google Forms responses and the Diagnostic Workbook.
A4: Legend
A5: Blue text on cream | B5: [INPUT] — the analyst types or pastes
A6: Black text | B6: [CALCULATED] — the workbook computes; do not edit
A7: Green text | B7: Link pulling from another tab in this workbook
A9: Three input types (how data enters the Diagnostic Workbook downstream)
A10: Type A — raw survey item means (entered un-flipped; the Diagnostic Workbook flips and converts).
A11: Type B — structured counts (C2 per-domain, C3 band counts).
A12: Type C — finished module scores computed here per the Module Library bespoke rule.
A14: Engagement keys
A15: Client and unit name | B15: [unit name]
A16: Unit FTE
A17: Cadence (baseline / half-yearly / quarterly) | B17: baseline
A19: Audience headcounts (response-rate denominators)
A20: All-member (main survey)
A21: Managers
A22: Leadership team
A23: Team leaders
A24: DLP sampled participants
A26: Parameters
A27: C1 proficiency threshold (1-5) | B27: 3
A28: Default 3 (Proficient). Skills rated at or above this count as demonstrated.
A30: Team list (CII team-level) | D30: Decision types — M-O1-LT | G30: Decision sample — M-DLP-PART | K30: Role families — M-C1-MGR
A31: Team | B31: FTE | D31: Decision type | G31: Decision ID | H31: Class | K31: Role family | L31: FTE | M31: Req. skills

Sheet 2 Import Main
A1: Import — Main Survey (all-member)
A2: Paste the export (data rows only) into row 5 onward. Columns follow Blueprint order. Row 3 = reverse flag (screening only); row 4 = item ID. Blank module columns stay empty when not deployed.
C3: F | D3: F | E3: F | F3: F | G3: R | H3: F | I3: F | J3: F | K3: F | L3: R | M3: F | N3: F | O3: F | P3: F | Q3: R | R3: F | S3: F | T3: F | U3: R | V3: F | W3: F | X3: F | Y3: F | Z3: F | AA3: F | AB3: F | AC3: F | AD3: R | AE3: F | AF3: F | AG3: F | AH3: R | AI3: F | AJ3: F | AK3: F | AL3: F | AM3: R | AN3: F | AO3: F | AP3: F | AQ3: F | AR3: F | AS3: R | AT3: F | AU3: F | AV3: R | AW3: F | AX3: F | AY3: F | AZ3: F | BA3: F | BB3: R | BC3: F | BD3: F | BE3: F | BF3: F | BG3: R | BH3: F | BI3: F | BJ3: R | BK3: F | BL3: F | BM3: F | BN3: F | BO3: F | BP3: R | BQ3: F | BR3: F | BS3: F | BT3: R | BU3: R | BV3: F | BW3: F | BX3: F | BY3: F | BZ3: R | CA3: F | CB3: F | CC3: R | CD3: R | CE3: F | CF3: R | CH3: F | CI3: F | CJ3: F | CK3: R | CL3: F | CM3: F | CO3: F | CP3: F | CQ3: F | CR3: R | CS3: F | CT3: F | CV3: F | CW3: F | CX3: F | CY3: R | CZ3: F | DA3: F
A4: Timestamp | B4: Team | C4: CII-01 | D4: CII-02 | E4: CII-03 | F4: CII-04 | G4: CII-05 | H4: CII-06 | I4: CII-07 | J4: CII-08 | K4: CII-09 | L4: CII-10 | M4: CII-11 | N4: CII-12 | O4: CII-13 | P4: CII-14 | Q4: CII-15 | R4: MI1-01 | S4: MI1-02 | T4: MI1-03 | U4: MI1-04 | V4: MI1-05 | W4: MI1-06 | X4: MI1-07 | Y4: MI1-08 | Z4: MI2-01 | AA4: MI2-02 | AB4: MI2-03 | AC4: MI2-04 | AD4: MI2-05 | AE4: MI3-01 | AF4: MI3-02 | AG4: MI3-03 | AH4: MI3-04 | AI4: MI3-05 | AJ4: MI4-01 | AK4: MI4-02 | AL4: MI4-03 | AM4: MI4-04 | AN4: TW-01 | AO4: TW-02 | AP4: TW-03 | AQ4: OI1-01 | AR4: OI1-02 | AS4: OI1-03 | AT4: OI1-04 | AU4: OI1-05 | AV4: OI1-06 | AW4: OI1-07 | AX4: OI1-08 | AY4: OI2-01 | AZ4: OI2-02 | BA4: OI2-03 | BB4: OI2-04 | BC4: OI3-01 | BD4: OI3-02 | BE4: OI3-03 | BF4: OI3-04 | BG4: OI3-05 | BH4: OI4-01 | BI4: OI4-02 | BJ4: OI4-03 | BK4: OI5-01 | BL4: OI5-02 | BM4: OI5-03 | BN4: TSI2-01 | BO4: TSI2-02 | BP4: TSI2-03 | BQ4: TSI3-01 | BR4: TSI3-02 | BS4: TSI3-03 | BT4: TSI3-04 | BU4: TSI3-05 | BV4: O1C-01 | BW4: O1C-02 | BX4: O1C-03 | BY4: O1C-04 | BZ4: O1C-05 | CA4: O2I-01 | CB4: O2I-02 | CC4: O2I-03 | CD4: O2I-04 | CE4: O2I-05 | CF4: O2I-06 | CG4: O2I-07 | CH4: P1 O3P-01 | CI4: P1 O3P-02 | CJ4: P1 O3P-03 | CK4: P1 O3P-04 | CL4: P1 O3P-05 | CM4: P1 O3P-06 | CN4: P1 O3P-07 | CO4: P2 O3P-01 | CP4: P2 O3P-02 | CQ4: P2 O3P-03 | CR4: P2 O3P-04 | CS4: P2 O3P-05 | CT4: P2 O3P-06 | CU4: P2 O3P-07 | CV4: P3 O3P-01 | CW4: P3 O3P-02 | CX4: P3 O3P-03 | CY4: P3 O3P-04 | CZ4: P3 O3P-05 | DA4: P3 O3P-06 | DB4: P3 O3P-07

Sheet 3 Import Manager
A1: Import — Manager Survey (M-C1-MGR, M-C3-MGR)
A2: One row per direct report. Paste / enter columns A to S. Reshape the raw manager form into this long layout. Skills blank where not used.
A4: Manager ID | B4: Role family | C4: Direct report | D4: Skill 01 | E4: Skill 02 | F4: Skill 03 | G4: Skill 04 | H4: Skill 05 | I4: Skill 06 | J4: Skill 07 | K4: Skill 08 | L4: Skill 09 | M4: Skill 10 | N4: Skill 11 | O4: Skill 12 | P4: Skill 13 | Q4: Skill 14 | R4: Skill 15 | S4: C3 Band (1-5) | T4: C1 coverage | U4: New mgr?
T5: =IF(OR(C5="",IFERROR(VLOOKUP(B5,'1 Setup & Keys'!$K$32:$M$41,3,FALSE()),"")=""),"",IFERROR(COUNTIF(D5:R5,">="&'1 Setup & Keys'!$B$27)/IFERROR(VLOOKUP(B5,'1 Setup & Keys'!$K$32:$M$41,3,FALSE()),""),"")) | U5: =IF(A5="",0,IF(COUNTIF($A$5:A5,A5)=1,1,0)) -> 0
T6: =IF(OR(C6="",IFERROR(VLOOKUP(B6,'1 Setup & Keys'!$K$32:$M$41,3,FALSE()),"")=""),"",IFERROR(COUNTIF(D6:R6,">="&'1 Setup & Keys'!$B$27)/IFERROR(VLOOKUP(B6,'1 Setup & Keys'!$K$32:$M$41,3,FALSE()),""),"")) | U6: =IF(A6="",0,IF(COUNTIF($A$5:A6,A6)=1,1,0)) -> 0
T7: =IF(OR(C7="",IFERROR(VLOOKUP(B7,'1 Setup & Keys'!$K$32:$M$41,3,FALSE()),"")=""),"",IFERROR(COUNTIF(D7:R7,">="&'1 Setup & Keys'!$B$27)/IFERROR(VLOOKUP(B7,'1 Setup & Keys'!$K$32:$M$41,3,FALSE()),""),"")) | U7: =IF(A7="",0,IF(COUNTIF($A$5:A7,A7)=1,1,0)) -> 0
T8: =IF(OR(C8="",IFERROR(VLOOKUP(B8,'1 Setup & Keys'!$K$32:$M$41,3,FALSE()),"")=""),"",IFERROR(COUNTIF(D8:R8,">="&'1 Setup & Keys'!$B$27)/IFERROR(VLOOKUP(B8,'1 Setup & Keys'!$K$32:$M$41,3,FALSE()),""),"")) | U8: =IF(A8="",0,IF(COUNTIF($A$5:A8,A8)=1,1,0)) -> 0
T9: =IF(OR(C9="",IFERROR(VLOOKUP(B9,'1 Setup & Keys'!$K$32:$M$41,3,FALSE()),"")=""),"",IFERROR(COUNTIF(D9:R9,">="&'1 Setup & Keys'!$B$27)/IFERROR(VLOOKUP(B9,'1 Setup & Keys'!$K$32:$M$41,3,FALSE()),""),"")) | U9: =IF(A9="",0,IF(COUNTIF($A$5:A9,A9)=1,1,0)) -> 0
T10: =IF(OR(C10="",IFERROR(VLOOKUP(B10,'1 Setup & Keys'!$K$32:$M$41,3,FALSE()),"")=""),"",IFERROR(COUNTIF(D10:R10,">="&'1 Setup & Keys'!$B$27)/IFERROR(VLOOKUP(B10,'1 Setup & Keys'!$K$32:$M$41,3,FALSE()),""),"")) | U10: =IF(A10="",0,IF(COUNTIF($A$5:A10,A10)=1,1,0)) -> 0
T11: =IF(OR(C11="",IFERROR(VLOOKUP(B11,'1 Setup & Keys'!$K$32:$M$41,3,FALSE()),"")=""),"",IFERROR(COUNTIF(D11:R11,">="&'1 Setup & Keys'!$B$27)/IFERROR(VLOOKUP(B11,'1 Setup & Keys'!$K$32:$M$41,3,FALSE()),""),"")) | U11: =IF(A11="",0,IF(COUNTIF($A$5:A11,A11)=1,1,0)) -> 0
T12: =IF(OR(C12="",IFERROR(VLOOKUP(B12,'1 Setup & Keys'!$K$32:$M$41,3,FALSE()),"")=""),"",IFERROR(COUNTIF(D12:R12,">="&'1 Setup & Keys'!$B$27)/IFERROR(VLOOKUP(B12,'1 Setup & Keys'!$K$32:$M$41,3,FALSE()),""),"")) | U12: =IF(A12="",0,IF(COUNTIF($A$5:A12,A12)=1,1,0)) -> 0
T13: =IF(OR(C13="",IFERROR(VLOOKUP(B13,'1 Setup & Keys'!$K$32:$M$41,3,FALSE()),"")=""),"",IFERROR(COUNTIF(D13:R13,">="&'1 Setup & Keys'!$B$27)/IFERROR(VLOOKUP(B13,'1 Setup & Keys'!$K$32:$M$41,3,FALSE()),""),"")) | U13: =IF(A13="",0,IF(COUNTIF($A$5:A13,A13)=1,1,0)) -> 0
T14: =IF(OR(C14="",IFERROR(VLOOKUP(B14,'1 Setup & Keys'!$K$32:$M$41,3,FALSE()),"")=""),"",IFERROR(COUNTIF(D14:R14,">="&'1 Setup & Keys'!$B$27)/IFERROR(VLOOKUP(B14,'1 Setup & Keys'!$K$32:$M$41,3,FALSE()),""),"")) | U14: =IF(A14="",0,IF(COUNTIF($A$5:A14,A14)=1,1,0)) -> 0
T15: =IF(OR(C15="",IFERROR(VLOOKUP(B15,'1 Setup & Keys'!$K$32:$M$41,3,FALSE()),"")=""),"",IFERROR(COUNTIF(D15:R15,">="&'1 Setup & Keys'!$B$27)/IFERROR(VLOOKUP(B15,'1 Setup & Keys'!$K$32:$M$41,3,FALSE()),""),"")) | U15: =IF(A15="",0,IF(COUNTIF($A$5:A15,A15)=1,1,0)) -> 0
T16: =IF(OR(C16="",IFERROR(VLOOKUP(B16,'1 Setup & Keys'!$K$32:$M$41,3,FALSE()),"")=""),"",IFERROR(COUNTIF(D16:R16,">="&'1 Setup & Keys'!$B$27)/IFERROR(VLOOKUP(B16,'1 Setup & Keys'!$K$32:$M$41,3,FALSE()),""),"")) | U16: =IF(A16="",0,IF(COUNTIF($A$5:A16,A16)=1,1,0)) -> 0
... T154: =IF(OR(C154="",IFERROR(VLOOKUP(B154,'1 Setup & Keys'!$K$32:$M$41,3,FALSE()),"")=""),"",IFERROR(COUNTIF(D154:R154,">="&'1 Setup & Keys'!$B$27)/IFERROR(VLOOKUP(B154,'1 Setup & Keys'!$K$32:$M$41,3,FALSE()),""),"")) | U154: =IF(A154="",0,IF(COUNTIF($A$5:A154,A154)=1,1,0)) -> 0

Sheet 4 Import Leadership
A1: Import — Leadership Survey (M-O1-LT, decision rights)
A2: One row per respondent per decision. Enter A to H. Helper columns I to N are calculated.
A4: Respondent | B4: Decision ID | C4: Recommend | D4: Agree | E4: Perform | F4: Input | G4: Decides | H4: Clarity (1-5) | I4: cntR | J4: cntA | K4: cntP | L4: cntI | M4: cntD | N4: New resp?
I5: =IF(OR($B5="",C5=""),"",COUNTIFS($B$5:$B$154,$B5,C$5:C$154,C5)) | J5: =IF(OR($B5="",D5=""),"",COUNTIFS($B$5:$B$154,$B5,D$5:D$154,D5)) | K5: =IF(OR($B5="",E5=""),"",COUNTIFS($B$5:$B$154,$B5,E$5:E$154,E5)) | L5: =IF(OR($B5="",F5=""),"",COUNTIFS($B$5:$B$154,$B5,F$5:F$154,F5)) | M5: =IF(OR($B5="",G5=""),"",COUNTIFS($B$5:$B$154,$B5,G$5:G$154,G5)) | N5: =IF(A5="",0,IF(COUNTIF($A$5:A5,A5)=1,1,0)) -> 0
I6: =IF(OR($B6="",C6=""),"",COUNTIFS($B$5:$B$154,$B6,C$5:C$154,C6)) | J6: =IF(OR($B6="",D6=""),"",COUNTIFS($B$5:$B$154,$B6,D$5:D$154,D6)) | K6: =IF(OR($B6="",E6=""),"",COUNTIFS($B$5:$B$154,$B6,E$5:E$154,E6)) | L6: =IF(OR($B6="",F6=""),"",COUNTIFS($B$5:$B$154,$B6,F$5:F$154,F6)) | M6: =IF(OR($B6="",G6=""),"",COUNTIFS($B$5:$B$154,$B6,G$5:G$154,G6)) | N6: =IF(A6="",0,IF(COUNTIF($A$5:A6,A6)=1,1,0)) -> 0
I7: =IF(OR($B7="",C7=""),"",COUNTIFS($B$5:$B$154,$B7,C$5:C$154,C7)) | J7: =IF(OR($B7="",D7=""),"",COUNTIFS($B$5:$B$154,$B7,D$5:D$154,D7)) | K7: =IF(OR($B7="",E7=""),"",COUNTIFS($B$5:$B$154,$B7,E$5:E$154,E7)) | L7: =IF(OR($B7="",F7=""),"",COUNTIFS($B$5:$B$154,$B7,F$5:F$154,F7)) | M7: =IF(OR($B7="",G7=""),"",COUNTIFS($B$5:$B$154,$B7,G$5:G$154,G7)) | N7: =IF(A7="",0,IF(COUNTIF($A$5:A7,A7)=1,1,0)) -> 0
I8: =IF(OR($B8="",C8=""),"",COUNTIFS($B$5:$B$154,$B8,C$5:C$154,C8)) | J8: =IF(OR($B8="",D8=""),"",COUNTIFS($B$5:$B$154,$B8,D$5:D$154,D8)) | K8: =IF(OR($B8="",E8=""),"",COUNTIFS($B$5:$B$154,$B8,E$5:E$154,E8)) | L8: =IF(OR($B8="",F8=""),"",COUNTIFS($B$5:$B$154,$B8,F$5:F$154,F8)) | M8: =IF(OR($B8="",G8=""),"",COUNTIFS($B$5:$B$154,$B8,G$5:G$154,G8)) | N8: =IF(A8="",0,IF(COUNTIF($A$5:A8,A8)=1,1,0)) -> 0
I9: =IF(OR($B9="",C9=""),"",COUNTIFS($B$5:$B$154,$B9,C$5:C$154,C9)) | J9: =IF(OR($B9="",D9=""),"",COUNTIFS($B$5:$B$154,$B9,D$5:D$154,D9)) | K9: =IF(OR($B9="",E9=""),"",COUNTIFS($B$5:$B$154,$B9,E$5:E$154,E9)) | L9: =IF(OR($B9="",F9=""),"",COUNTIFS($B$5:$B$154,$B9,F$5:F$154,F9)) | M9: =IF(OR($B9="",G9=""),"",COUNTIFS($B$5:$B$154,$B9,G$5:G$154,G9)) | N9: =IF(A9="",0,IF(COUNTIF($A$5:A9,A9)=1,1,0)) -> 0
I10: =IF(OR($B10="",C10=""),"",COUNTIFS($B$5:$B$154,$B10,C$5:C$154,C10)) | J10: =IF(OR($B10="",D10=""),"",COUNTIFS($B$5:$B$154,$B10,D$5:D$154,D10)) | K10: =IF(OR($B10="",E10=""),"",COUNTIFS($B$5:$B$154,$B10,E$5:E$154,E10)) | L10: =IF(OR($B10="",F10=""),"",COUNTIFS($B$5:$B$154,$B10,F$5:F$154,F10)) | M10: =IF(OR($B10="",G10=""),"",COUNTIFS($B$5:$B$154,$B10,G$5:G$154,G10)) | N10: =IF(A10="",0,IF(COUNTIF($A$5:A10,A10)=1,1,0)) -> 0
I11: =IF(OR($B11="",C11=""),"",COUNTIFS($B$5:$B$154,$B11,C$5:C$154,C11)) | J11: =IF(OR($B11="",D11=""),"",COUNTIFS($B$5:$B$154,$B11,D$5:D$154,D11)) | K11: =IF(OR($B11="",E11=""),"",COUNTIFS($B$5:$B$154,$B11,E$5:E$154,E11)) | L11: =IF(OR($B11="",F11=""),"",COUNTIFS($B$5:$B$154,$B11,F$5:F$154,F11)) | M11: =IF(OR($B11="",G11=""),"",COUNTIFS($B$5:$B$154,$B11,G$5:G$154,G11)) | N11: =IF(A11="",0,IF(COUNTIF($A$5:A11,A11)=1,1,0)) -> 0
I12: =IF(OR($B12="",C12=""),"",COUNTIFS($B$5:$B$154,$B12,C$5:C$154,C12)) | J12: =IF(OR($B12="",D12=""),"",COUNTIFS($B$5:$B$154,$B12,D$5:D$154,D12)) | K12: =IF(OR($B12="",E12=""),"",COUNTIFS($B$5:$B$154,$B12,E$5:E$154,E12)) | L12: =IF(OR($B12="",F12=""),"",COUNTIFS($B$5:$B$154,$B12,F$5:F$154,F12)) | M12: =IF(OR($B12="",G12=""),"",COUNTIFS($B$5:$B$154,$B12,G$5:G$154,G12)) | N12: =IF(A12="",0,IF(COUNTIF($A$5:A12,A12)=1,1,0)) -> 0
I13: =IF(OR($B13="",C13=""),"",COUNTIFS($B$5:$B$154,$B13,C$5:C$154,C13)) | J13: =IF(OR($B13="",D13=""),"",COUNTIFS($B$5:$B$154,$B13,D$5:D$154,D13)) | K13: =IF(OR($B13="",E13=""),"",COUNTIFS($B$5:$B$154,$B13,E$5:E$154,E13)) | L13: =IF(OR($B13="",F13=""),"",COUNTIFS($B$5:$B$154,$B13,F$5:F$154,F13)) | M13: =IF(OR($B13="",G13=""),"",COUNTIFS($B$5:$B$154,$B13,G$5:G$154,G13)) | N13: =IF(A13="",0,IF(COUNTIF($A$5:A13,A13)=1,1,0)) -> 0
I14: =IF(OR($B14="",C14=""),"",COUNTIFS($B$5:$B$154,$B14,C$5:C$154,C14)) | J14: =IF(OR($B14="",D14=""),"",COUNTIFS($B$5:$B$154,$B14,D$5:D$154,D14)) | K14: =IF(OR($B14="",E14=""),"",COUNTIFS($B$5:$B$154,$B14,E$5:E$154,E14)) | L14: =IF(OR($B14="",F14=""),"",COUNTIFS($B$5:$B$154,$B14,F$5:F$154,F14)) | M14: =IF(OR($B14="",G14=""),"",COUNTIFS($B$5:$B$154,$B14,G$5:G$154,G14)) | N14: =IF(A14="",0,IF(COUNTIF($A$5:A14,A14)=1,1,0)) -> 0
I15: =IF(OR($B15="",C15=""),"",COUNTIFS($B$5:$B$154,$B15,C$5:C$154,C15)) | J15: =IF(OR($B15="",D15=""),"",COUNTIFS($B$5:$B$154,$B15,D$5:D$154,D15)) | K15: =IF(OR($B15="",E15=""),"",COUNTIFS($B$5:$B$154,$B15,E$5:E$154,E15)) | L15: =IF(OR($B15="",F15=""),"",COUNTIFS($B$5:$B$154,$B15,F$5:F$154,F15)) | M15: =IF(OR($B15="",G15=""),"",COUNTIFS($B$5:$B$154,$B15,G$5:G$154,G15)) | N15: =IF(A15="",0,IF(COUNTIF($A$5:A15,A15)=1,1,0)) -> 0
I16: =IF(OR($B16="",C16=""),"",COUNTIFS($B$5:$B$154,$B16,C$5:C$154,C16)) | J16: =IF(OR($B16="",D16=""),"",COUNTIFS($B$5:$B$154,$B16,D$5:D$154,D16)) | K16: =IF(OR($B16="",E16=""),"",COUNTIFS($B$5:$B$154,$B16,E$5:E$154,E16)) | L16: =IF(OR($B16="",F16=""),"",COUNTIFS($B$5:$B$154,$B16,F$5:F$154,F16)) | M16: =IF(OR($B16="",G16=""),"",COUNTIFS($B$5:$B$154,$B16,G$5:G$154,G16)) | N16: =IF(A16="",0,IF(COUNTIF($A$5:A16,A16)=1,1,0)) -> 0
... I154: =IF(OR($B154="",C154=""),"",COUNTIFS($B$5:$B$154,$B154,C$5:C$154,C154)) | J154: =IF(OR($B154="",D154=""),"",COUNTIFS($B$5:$B$154,$B154,D$5:D$154,D154)) | K154: =IF(OR($B154="",E154=""),"",COUNTIFS($B$5:$B$154,$B154,E$5:E$154,E154)) | L154: =IF(OR($B154="",F154=""),"",COUNTIFS($B$5:$B$154,$B154,F$5:F$154,F154)) | M154: =IF(OR($B154="",G154=""),"",COUNTIFS($B$5:$B$154,$B154,G$5:G$154,G154)) | N154: =IF(A154="",0,IF(COUNTIF($A$5:A154,A154)=1,1,0)) -> 0

Sheet 5 Import TeamLeader
A1: Import — Team-Leader Survey (M-C5-TL, learning velocity)
A2: One row per team leader. Enter the 12 calibrated items (1-5). Per-leader score is calculated.
A4: Team leader | B4: C5L-01 | C4: C5L-02 | D4: C5L-03 | E4: C5L-04 | F4: C5L-05 | G4: C5L-06 | H4: C5L-07 | I4: C5L-08 | J4: C5L-09 | K4: C5L-10 | L4: C5L-11 | M4: C5L-12 | N4: Per-leader score
N5: =IF(COUNT(B5:M5)=0,"",(AVERAGE(B5:M5)-1)*25)
N6: =IF(COUNT(B6:M6)=0,"",(AVERAGE(B6:M6)-1)*25)
N7: =IF(COUNT(B7:M7)=0,"",(AVERAGE(B7:M7)-1)*25)
N8: =IF(COUNT(B8:M8)=0,"",(AVERAGE(B8:M8)-1)*25)
N9: =IF(COUNT(B9:M9)=0,"",(AVERAGE(B9:M9)-1)*25)
N10: =IF(COUNT(B10:M10)=0,"",(AVERAGE(B10:M10)-1)*25)
N11: =IF(COUNT(B11:M11)=0,"",(AVERAGE(B11:M11)-1)*25)
N12: =IF(COUNT(B12:M12)=0,"",(AVERAGE(B12:M12)-1)*25)
N13: =IF(COUNT(B13:M13)=0,"",(AVERAGE(B13:M13)-1)*25)
N14: =IF(COUNT(B14:M14)=0,"",(AVERAGE(B14:M14)-1)*25)
N15: =IF(COUNT(B15:M15)=0,"",(AVERAGE(B15:M15)-1)*25)
N16: =IF(COUNT(B16:M16)=0,"",(AVERAGE(B16:M16)-1)*25)
... N44: =IF(COUNT(B44:M44)=0,"",(AVERAGE(B44:M44)-1)*25)

Sheet 6 Import DLP
A1: Import — DLP Survey (M-DLP-PART, decision latency)
A2: One row per respondent per decision. Enter A to F. Latency and distinct-respondent flag are calculated.
A4: Respondent | B4: Decision ID | C4: Date identified (DLP-01) | D4: Date authorised (DLP-02) | E4: Quality (1-3) | F4: Notes (pathway/delay/systemic) | G4: Latency (days) | H4: New resp?
G5: =IF(OR(C5="",D5=""),"",D5-C5) | H5: =IF(A5="",0,IF(COUNTIF($A$5:A5,A5)=1,1,0)) -> 0
G6: =IF(OR(C6="",D6=""),"",D6-C6) | H6: =IF(A6="",0,IF(COUNTIF($A$5:A6,A6)=1,1,0)) -> 0
G7: =IF(OR(C7="",D7=""),"",D7-C7) | H7: =IF(A7="",0,IF(COUNTIF($A$5:A7,A7)=1,1,0)) -> 0
G8: =IF(OR(C8="",D8=""),"",D8-C8) | H8: =IF(A8="",0,IF(COUNTIF($A$5:A8,A8)=1,1,0)) -> 0
G9: =IF(OR(C9="",D9=""),"",D9-C9) | H9: =IF(A9="",0,IF(COUNTIF($A$5:A9,A9)=1,1,0)) -> 0
G10: =IF(OR(C10="",D10=""),"",D10-C10) | H10: =IF(A10="",0,IF(COUNTIF($A$5:A10,A10)=1,1,0)) -> 0
G11: =IF(OR(C11="",D11=""),"",D11-C11) | H11: =IF(A11="",0,IF(COUNTIF($A$5:A11,A11)=1,1,0)) -> 0
G12: =IF(OR(C12="",D12=""),"",D12-C12) | H12: =IF(A12="",0,IF(COUNTIF($A$5:A12,A12)=1,1,0)) -> 0
G13: =IF(OR(C13="",D13=""),"",D13-C13) | H13: =IF(A13="",0,IF(COUNTIF($A$5:A13,A13)=1,1,0)) -> 0
G14: =IF(OR(C14="",D14=""),"",D14-C14) | H14: =IF(A14="",0,IF(COUNTIF($A$5:A14,A14)=1,1,0)) -> 0
G15: =IF(OR(C15="",D15=""),"",D15-C15) | H15: =IF(A15="",0,IF(COUNTIF($A$5:A15,A15)=1,1,0)) -> 0
G16: =IF(OR(C16="",D16=""),"",D16-C16) | H16: =IF(A16="",0,IF(COUNTIF($A$5:A16,A16)=1,1,0)) -> 0
... G204: =IF(OR(C204="",D204=""),"",D204-C204) | H204: =IF(A204="",0,IF(COUNTIF($A$5:A204,A204)=1,1,0)) -> 0

Sheet 7 Screening
A1: Response Screening (main survey)
A2: Validity flag per respondent. Means and all-member modules compute over VALID rows only. Speed-clicking not available on Google Forms (see footer).
A4: Row | B4: Answered | C4: Fwd mean (raw) | D4: Rev mean (raw) | E4: Max | F4: Min | G4: All-same | H4: Straight-lining | I4: VALID
A5: =IF(COUNT('2 Import Main'!C5:DB5)=0,"",5) | B5: =COUNT('2 Import Main'!C5:DB5) -> 0 | C5: =IFERROR(AVERAGEIF('2 Import Main'!$C$3:$DB$3,"F",'2 Import Main'!C5:DB5),"") | D5: =IFERROR(AVERAGEIF('2 Import Main'!$C$3:$DB$3,"R",'2 Import Main'!C5:DB5),"") | E5: =IFERROR(MAX('2 Import Main'!C5:DB5),"") -> 0 | F5: =IFERROR(MIN('2 Import Main'!C5:DB5),"") -> 0 | G5: =IF(B5=0,"",IF(E5=F5,1,0)) | H5: =IF(OR(B5=0,C5="",D5=""),0,IF(OR(AND(C5>=4,D5>=4),AND(C5<=2,D5<=2)),1,0)) -> 0 | I5: =IF(B5=0,"",IF(OR(G5=1,H5=1),0,1))
A6: =IF(COUNT('2 Import Main'!C6:DB6)=0,"",6) | B6: =COUNT('2 Import Main'!C6:DB6) -> 0 | C6: =IFERROR(AVERAGEIF('2 Import Main'!$C$3:$DB$3,"F",'2 Import Main'!C6:DB6),"") | D6: =IFERROR(AVERAGEIF('2 Import Main'!$C$3:$DB$3,"R",'2 Import Main'!C6:DB6),"") | E6: =IFERROR(MAX('2 Import Main'!C6:DB6),"") -> 0 | F6: =IFERROR(MIN('2 Import Main'!C6:DB6),"") -> 0 | G6: =IF(B6=0,"",IF(E6=F6,1,0)) | H6: =IF(OR(B6=0,C6="",D6=""),0,IF(OR(AND(C6>=4,D6>=4),AND(C6<=2,D6<=2)),1,0)) -> 0 | I6: =IF(B6=0,"",IF(OR(G6=1,H6=1),0,1))
A7: =IF(COUNT('2 Import Main'!C7:DB7)=0,"",7) | B7: =COUNT('2 Import Main'!C7:DB7) -> 0 | C7: =IFERROR(AVERAGEIF('2 Import Main'!$C$3:$DB$3,"F",'2 Import Main'!C7:DB7),"") | D7: =IFERROR(AVERAGEIF('2 Import Main'!$C$3:$DB$3,"R",'2 Import Main'!C7:DB7),"") | E7: =IFERROR(MAX('2 Import Main'!C7:DB7),"") -> 0 | F7: =IFERROR(MIN('2 Import Main'!C7:DB7),"") -> 0 | G7: =IF(B7=0,"",IF(E7=F7,1,0)) | H7: =IF(OR(B7=0,C7="",D7=""),0,IF(OR(AND(C7>=4,D7>=4),AND(C7<=2,D7<=2)),1,0)) -> 0 | I7: =IF(B7=0,"",IF(OR(G7=1,H7=1),0,1))
A8: =IF(COUNT('2 Import Main'!C8:DB8)=0,"",8) | B8: =COUNT('2 Import Main'!C8:DB8) -> 0 | C8: =IFERROR(AVERAGEIF('2 Import Main'!$C$3:$DB$3,"F",'2 Import Main'!C8:DB8),"") | D8: =IFERROR(AVERAGEIF('2 Import Main'!$C$3:$DB$3,"R",'2 Import Main'!C8:DB8),"") | E8: =IFERROR(MAX('2 Import Main'!C8:DB8),"") -> 0 | F8: =IFERROR(MIN('2 Import Main'!C8:DB8),"") -> 0 | G8: =IF(B8=0,"",IF(E8=F8,1,0)) | H8: =IF(OR(B8=0,C8="",D8=""),0,IF(OR(AND(C8>=4,D8>=4),AND(C8<=2,D8<=2)),1,0)) -> 0 | I8: =IF(B8=0,"",IF(OR(G8=1,H8=1),0,1))
A9: =IF(COUNT('2 Import Main'!C9:DB9)=0,"",9) | B9: =COUNT('2 Import Main'!C9:DB9) -> 0 | C9: =IFERROR(AVERAGEIF('2 Import Main'!$C$3:$DB$3,"F",'2 Import Main'!C9:DB9),"") | D9: =IFERROR(AVERAGEIF('2 Import Main'!$C$3:$DB$3,"R",'2 Import Main'!C9:DB9),"") | E9: =IFERROR(MAX('2 Import Main'!C9:DB9),"") -> 0 | F9: =IFERROR(MIN('2 Import Main'!C9:DB9),"") -> 0 | G9: =IF(B9=0,"",IF(E9=F9,1,0)) | H9: =IF(OR(B9=0,C9="",D9=""),0,IF(OR(AND(C9>=4,D9>=4),AND(C9<=2,D9<=2)),1,0)) -> 0 | I9: =IF(B9=0,"",IF(OR(G9=1,H9=1),0,1))
A10: =IF(COUNT('2 Import Main'!C10:DB10)=0,"",10) | B10: =COUNT('2 Import Main'!C10:DB10) -> 0 | C10: =IFERROR(AVERAGEIF('2 Import Main'!$C$3:$DB$3,"F",'2 Import Main'!C10:DB10),"") | D10: =IFERROR(AVERAGEIF('2 Import Main'!$C$3:$DB$3,"R",'2 Import Main'!C10:DB10),"") | E10: =IFERROR(MAX('2 Import Main'!C10:DB10),"") -> 0 | F10: =IFERROR(MIN('2 Import Main'!C10:DB10),"") -> 0 | G10: =IF(B10=0,"",IF(E10=F10,1,0)) | H10: =IF(OR(B10=0,C10="",D10=""),0,IF(OR(AND(C10>=4,D10>=4),AND(C10<=2,D10<=2)),1,0)) -> 0 | I10: =IF(B10=0,"",IF(OR(G10=1,H10=1),0,1))
A11: =IF(COUNT('2 Import Main'!C11:DB11)=0,"",11) | B11: =COUNT('2 Import Main'!C11:DB11) -> 0 | C11: =IFERROR(AVERAGEIF('2 Import Main'!$C$3:$DB$3,"F",'2 Import Main'!C11:DB11),"") | D11: =IFERROR(AVERAGEIF('2 Import Main'!$C$3:$DB$3,"R",'2 Import Main'!C11:DB11),"") | E11: =IFERROR(MAX('2 Import Main'!C11:DB11),"") -> 0 | F11: =IFERROR(MIN('2 Import Main'!C11:DB11),"") -> 0 | G11: =IF(B11=0,"",IF(E11=F11,1,0)) | H11: =IF(OR(B11=0,C11="",D11=""),0,IF(OR(AND(C11>=4,D11>=4),AND(C11<=2,D11<=2)),1,0)) -> 0 | I11: =IF(B11=0,"",IF(OR(G11=1,H11=1),0,1))
A12: =IF(COUNT('2 Import Main'!C12:DB12)=0,"",12) | B12: =COUNT('2 Import Main'!C12:DB12) -> 0 | C12: =IFERROR(AVERAGEIF('2 Import Main'!$C$3:$DB$3,"F",'2 Import Main'!C12:DB12),"") | D12: =IFERROR(AVERAGEIF('2 Import Main'!$C$3:$DB$3,"R",'2 Import Main'!C12:DB12),"") | E12: =IFERROR(MAX('2 Import Main'!C12:DB12),"") -> 0 | F12: =IFERROR(MIN('2 Import Main'!C12:DB12),"") -> 0 | G12: =IF(B12=0,"",IF(E12=F12,1,0)) | H12: =IF(OR(B12=0,C12="",D12=""),0,IF(OR(AND(C12>=4,D12>=4),AND(C12<=2,D12<=2)),1,0)) -> 0 | I12: =IF(B12=0,"",IF(OR(G12=1,H12=1),0,1))
A13: =IF(COUNT('2 Import Main'!C13:DB13)=0,"",13) | B13: =COUNT('2 Import Main'!C13:DB13) -> 0 | C13: =IFERROR(AVERAGEIF('2 Import Main'!$C$3:$DB$3,"F",'2 Import Main'!C13:DB13),"") | D13: =IFERROR(AVERAGEIF('2 Import Main'!$C$3:$DB$3,"R",'2 Import Main'!C13:DB13),"") | E13: =IFERROR(MAX('2 Import Main'!C13:DB13),"") -> 0 | F13: =IFERROR(MIN('2 Import Main'!C13:DB13),"") -> 0 | G13: =IF(B13=0,"",IF(E13=F13,1,0)) | H13: =IF(OR(B13=0,C13="",D13=""),0,IF(OR(AND(C13>=4,D13>=4),AND(C13<=2,D13<=2)),1,0)) -> 0 | I13: =IF(B13=0,"",IF(OR(G13=1,H13=1),0,1))
A14: =IF(COUNT('2 Import Main'!C14:DB14)=0,"",14) | B14: =COUNT('2 Import Main'!C14:DB14) -> 0 | C14: =IFERROR(AVERAGEIF('2 Import Main'!$C$3:$DB$3,"F",'2 Import Main'!C14:DB14),"") | D14: =IFERROR(AVERAGEIF('2 Import Main'!$C$3:$DB$3,"R",'2 Import Main'!C14:DB14),"") | E14: =IFERROR(MAX('2 Import Main'!C14:DB14),"") -> 0 | F14: =IFERROR(MIN('2 Import Main'!C14:DB14),"") -> 0 | G14: =IF(B14=0,"",IF(E14=F14,1,0)) | H14: =IF(OR(B14=0,C14="",D14=""),0,IF(OR(AND(C14>=4,D14>=4),AND(C14<=2,D14<=2)),1,0)) -> 0 | I14: =IF(B14=0,"",IF(OR(G14=1,H14=1),0,1))
A15: =IF(COUNT('2 Import Main'!C15:DB15)=0,"",15) | B15: =COUNT('2 Import Main'!C15:DB15) -> 0 | C15: =IFERROR(AVERAGEIF('2 Import Main'!$C$3:$DB$3,"F",'2 Import Main'!C15:DB15),"") | D15: =IFERROR(AVERAGEIF('2 Import Main'!$C$3:$DB$3,"R",'2 Import Main'!C15:DB15),"") | E15: =IFERROR(MAX('2 Import Main'!C15:DB15),"") -> 0 | F15: =IFERROR(MIN('2 Import Main'!C15:DB15),"") -> 0 | G15: =IF(B15=0,"",IF(E15=F15,1,0)) | H15: =IF(OR(B15=0,C15="",D15=""),0,IF(OR(AND(C15>=4,D15>=4),AND(C15<=2,D15<=2)),1,0)) -> 0 | I15: =IF(B15=0,"",IF(OR(G15=1,H15=1),0,1))
A16: =IF(COUNT('2 Import Main'!C16:DB16)=0,"",16) | B16: =COUNT('2 Import Main'!C16:DB16) -> 0 | C16: =IFERROR(AVERAGEIF('2 Import Main'!$C$3:$DB$3,"F",'2 Import Main'!C16:DB16),"") | D16: =IFERROR(AVERAGEIF('2 Import Main'!$C$3:$DB$3,"R",'2 Import Main'!C16:DB16),"") | E16: =IFERROR(MAX('2 Import Main'!C16:DB16),"") -> 0 | F16: =IFERROR(MIN('2 Import Main'!C16:DB16),"") -> 0 | G16: =IF(B16=0,"",IF(E16=F16,1,0)) | H16: =IF(OR(B16=0,C16="",D16=""),0,IF(OR(AND(C16>=4,D16>=4),AND(C16<=2,D16<=2)),1,0)) -> 0 | I16: =IF(B16=0,"",IF(OR(G16=1,H16=1),0,1))
A17: =IF(COUNT('2 Import Main'!C17:DB17)=0,"",17) | B17: =COUNT('2 Import Main'!C17:DB17) -> 0 | C17: =IFERROR(AVERAGEIF('2 Import Main'!$C$3:$DB$3,"F",'2 Import Main'!C17:DB17),"") | D17: =IFERROR(AVERAGEIF('2 Import Main'!$C$3:$DB$3,"R",'2 Import Main'!C17:DB17),"") | E17: =IFERROR(MAX('2 Import Main'!C17:DB17),"") -> 0 | F17: =IFERROR(MIN('2 Import Main'!C17:DB17),"") -> 0 | G17: =IF(B17=0,"",IF(E17=F17,1,0)) | H17: =IF(OR(B17=0,C17="",D17=""),0,IF(OR(AND(C17>=4,D17>=4),AND(C17<=2,D17<=2)),1,0)) -> 0 | I17: =IF(B17=0,"",IF(OR(G17=1,H17=1),0,1))
A18: =IF(COUNT('2 Import Main'!C18:DB18)=0,"",18) | B18: =COUNT('2 Import Main'!C18:DB18) -> 0 | C18: =IFERROR(AVERAGEIF('2 Import Main'!$C$3:$DB$3,"F",'2 Import Main'!C18:DB18),"") | D18: =IFERROR(AVERAGEIF('2 Import Main'!$C$3:$DB$3,"R",'2 Import Main'!C18:DB18),"") | E18: =IFERROR(MAX('2 Import Main'!C18:DB18),"") -> 0 | F18: =IFERROR(MIN('2 Import Main'!C18:DB18),"") -> 0 | G18: =IF(B18=0,"",IF(E18=F18,1,0)) | H18: =IF(OR(B18=0,C18="",D18=""),0,IF(OR(AND(C18>=4,D18>=4),AND(C18<=2,D18<=2)),1,0)) -> 0 | I18: =IF(B18=0,"",IF(OR(G18=1,H18=1),0,1))
A19: =IF(COUNT('2 Import Main'!C19:DB19)=0,"",19) | B19: =COUNT('2 Import Main'!C19:DB19) -> 0 | C19: =IFERROR(AVERAGEIF('2 Import Main'!$C$3:$DB$3,"F",'2 Import Main'!C19:DB19),"") | D19: =IFERROR(AVERAGEIF('2 Import Main'!$C$3:$DB$3,"R",'2 Import Main'!C19:DB19),"") | E19: =IFERROR(MAX('2 Import Main'!C19:DB19),"") -> 0 | F19: =IFERROR(MIN('2 Import Main'!C19:DB19),"") -> 0 | G19: =IF(B19=0,"",IF(E19=F19,1,0)) | H19: =IF(OR(B19=0,C19="",D19=""),0,IF(OR(AND(C19>=4,D19>=4),AND(C19<=2,D19<=2)),1,0)) -> 0 | I19: =IF(B19=0,"",IF(OR(G19=1,H19=1),0,1))
A20: =IF(COUNT('2 Import Main'!C20:DB20)=0,"",20) | B20: =COUNT('2 Import Main'!C20:DB20) -> 0 | C20: =IFERROR(AVERAGEIF('2 Import Main'!$C$3:$DB$3,"F",'2 Import Main'!C20:DB20),"") | D20: =IFERROR(AVERAGEIF('2 Import Main'!$C$3:$DB$3,"R",'2 Import Main'!C20:DB20),"") | E20: =IFERROR(MAX('2 Import Main'!C20:DB20),"") -> 0 | F20: =IFERROR(MIN('2 Import Main'!C20:DB20),"") -> 0 | G20: =IF(B20=0,"",IF(E20=F20,1,0)) | H20: =IF(OR(B20=0,C20="",D20=""),0,IF(OR(AND(C20>=4,D20>=4),AND(C20<=2,D20<=2)),1,0)) -> 0 | I20: =IF(B20=0,"",IF(OR(G20=1,H20=1),0,1))
A21: =IF(COUNT('2 Import Main'!C21:DB21)=0,"",21) | B21: =COUNT('2 Import Main'!C21:DB21) -> 0 | C21: =IFERROR(AVERAGEIF('2 Import Main'!$C$3:$DB$3,"F",'2 Import Main'!C21:DB21),"") | D21: =IFERROR(AVERAGEIF('2 Import Main'!$C$3:$DB$3,"R",'2 Import Main'!C21:DB21),"") | E21: =IFERROR(MAX('2 Import Main'!C21:DB21),"") -> 0 | F21: =IFERROR(MIN('2 Import Main'!C21:DB21),"") -> 0 | G21: =IF(B21=0,"",IF(E21=F21,1,0)) | H21: =IF(OR(B21=0,C21="",D21=""),0,IF(OR(AND(C21>=4,D21>=4),AND(C21<=2,D21<=2)),1,0)) -> 0 | I21: =IF(B21=0,"",IF(OR(G21=1,H21=1),0,1))
A22: =IF(COUNT('2 Import Main'!C22:DB22)=0,"",22) | B22: =COUNT('2 Import Main'!C22:DB22) -> 0 | C22: =IFERROR(AVERAGEIF('2 Import Main'!$C$3:$DB$3,"F",'2 Import Main'!C22:DB22),"") | D22: =IFERROR(AVERAGEIF('2 Import Main'!$C$3:$DB$3,"R",'2 Import Main'!C22:DB22),"") | E22: =IFERROR(MAX('2 Import Main'!C22:DB22),"") -> 0 | F22: =IFERROR(MIN('2 Import Main'!C22:DB22),"") -> 0 | G22: =IF(B22=0,"",IF(E22=F22,1,0)) | H22: =IF(OR(B22=0,C22="",D22=""),0,IF(OR(AND(C22>=4,D22>=4),AND(C22<=2,D22<=2)),1,0)) -> 0 | I22: =IF(B22=0,"",IF(OR(G22=1,H22=1),0,1))
A23: =IF(COUNT('2 Import Main'!C23:DB23)=0,"",23) | B23: =COUNT('2 Import Main'!C23:DB23) -> 0 | C23: =IFERROR(AVERAGEIF('2 Import Main'!$C$3:$DB$3,"F",'2 Import Main'!C23:DB23),"") | D23: =IFERROR(AVERAGEIF('2 Import Main'!$C$3:$DB$3,"R",'2 Import Main'!C23:DB23),"") | E23: =IFERROR(MAX('2 Import Main'!C23:DB23),"") -> 0 | F23: =IFERROR(MIN('2 Import Main'!C23:DB23),"") -> 0 | G23: =IF(B23=0,"",IF(E23=F23,1,0)) | H23: =IF(OR(B23=0,C23="",D23=""),0,IF(OR(AND(C23>=4,D23>=4),AND(C23<=2,D23<=2)),1,0)) -> 0 | I23: =IF(B23=0,"",IF(OR(G23=1,H23=1),0,1))
A24: =IF(COUNT('2 Import Main'!C24:DB24)=0,"",24) | B24: =COUNT('2 Import Main'!C24:DB24) -> 0 | C24: =IFERROR(AVERAGEIF('2 Import Main'!$C$3:$DB$3,"F",'2 Import Main'!C24:DB24),"") | D24: =IFERROR(AVERAGEIF('2 Import Main'!$C$3:$DB$3,"R",'2 Import Main'!C24:DB24),"") | E24: =IFERROR(MAX('2 Import Main'!C24:DB24),"") -> 0 | F24: =IFERROR(MIN('2 Import Main'!C24:DB24),"") -> 0 | G24: =IF(B24=0,"",IF(E24=F24,1,0)) | H24: =IF(OR(B24=0,C24="",D24=""),0,IF(OR(AND(C24>=4,D24>=4),AND(C24<=2,D24<=2)),1,0)) -> 0 | I24: =IF(B24=0,"",IF(OR(G24=1,H24=1),0,1))
A25: =IF(COUNT('2 Import Main'!C25:DB25)=0,"",25) | B25: =COUNT('2 Import Main'!C25:DB25) -> 0 | C25: =IFERROR(AVERAGEIF('2 Import Main'!$C$3:$DB$3,"F",'2 Import Main'!C25:DB25),"") | D25: =IFERROR(AVERAGEIF('2 Import Main'!$C$3:$DB$3,"R",'2 Import Main'!C25:DB25),"") | E25: =IFERROR(MAX('2 Import Main'!C25:DB25),"") -> 0 | F25: =IFERROR(MIN('2 Import Main'!C25:DB25),"") -> 0 | G25: =IF(B25=0,"",IF(E25=F25,1,0)) | H25: =IF(OR(B25=0,C25="",D25=""),0,IF(OR(AND(C25>=4,D25>=4),AND(C25<=2,D25<=2)),1,0)) -> 0 | I25: =IF(B25=0,"",IF(OR(G25=1,H25=1),0,1))
A26: =IF(COUNT('2 Import Main'!C26:DB26)=0,"",26) | B26: =COUNT('2 Import Main'!C26:DB26) -> 0 | C26: =IFERROR(AVERAGEIF('2 Import Main'!$C$3:$DB$3,"F",'2 Import Main'!C26:DB26),"") | D26: =IFERROR(AVERAGEIF('2 Import Main'!$C$3:$DB$3,"R",'2 Import Main'!C26:DB26),"") | E26: =IFERROR(MAX('2 Import Main'!C26:DB26),"") -> 0 | F26: =IFERROR(MIN('2 Import Main'!C26:DB26),"") -> 0 | G26: =IF(B26=0,"",IF(E26=F26,1,0)) | H26: =IF(OR(B26=0,C26="",D26=""),0,IF(OR(AND(C26>=4,D26>=4),AND(C26<=2,D26<=2)),1,0)) -> 0 | I26: =IF(B26=0,"",IF(OR(G26=1,H26=1),0,1))
A27: =IF(COUNT('2 Import Main'!C27:DB27)=0,"",27) | B27: =COUNT('2 Import Main'!C27:DB27) -> 0 | C27: =IFERROR(AVERAGEIF('2 Import Main'!$C$3:$DB$3,"F",'2 Import Main'!C27:DB27),"") | D27: =IFERROR(AVERAGEIF('2 Import Main'!$C$3:$DB$3,"R",'2 Import Main'!C27:DB27),"") | E27: =IFERROR(MAX('2 Import Main'!C27:DB27),"") -> 0 | F27: =IFERROR(MIN('2 Import Main'!C27:DB27),"") -> 0 | G27: =IF(B27=0,"",IF(E27=F27,1,0)) | H27: =IF(OR(B27=0,C27="",D27=""),0,IF(OR(AND(C27>=4,D27>=4),AND(C27<=2,D27<=2)),1,0)) -> 0 | I27: =IF(B27=0,"",IF(OR(G27=1,H27=1),0,1))
A28: =IF(COUNT('2 Import Main'!C28:DB28)=0,"",28) | B28: =COUNT('2 Import Main'!C28:DB28) -> 0 | C28: =IFERROR(AVERAGEIF('2 Import Main'!$C$3:$DB$3,"F",'2 Import Main'!C28:DB28),"") | D28: =IFERROR(AVERAGEIF('2 Import Main'!$C$3:$DB$3,"R",'2 Import Main'!C28:DB28),"") | E28: =IFERROR(MAX('2 Import Main'!C28:DB28),"") -> 0 | F28: =IFERROR(MIN('2 Import Main'!C28:DB28),"") -> 0 | G28: =IF(B28=0,"",IF(E28=F28,1,0)) | H28: =IF(OR(B28=0,C28="",D28=""),0,IF(OR(AND(C28>=4,D28>=4),AND(C28<=2,D28<=2)),1,0)) -> 0 | I28: =IF(B28=0,"",IF(OR(G28=1,H28=1),0,1))
A29: =IF(COUNT('2 Import Main'!C29:DB29)=0,"",29) | B29: =COUNT('2 Import Main'!C29:DB29) -> 0 | C29: =IFERROR(AVERAGEIF('2 Import Main'!$C$3:$DB$3,"F",'2 Import Main'!C29:DB29),"") | D29: =IFERROR(AVERAGEIF('2 Import Main'!$C$3:$DB$3,"R",'2 Import Main'!C29:DB29),"") | E29: =IFERROR(MAX('2 Import Main'!C29:DB29),"") -> 0 | F29: =IFERROR(MIN('2 Import Main'!C29:DB29),"") -> 0 | G29: =IF(B29=0,"",IF(E29=F29,1,0)) | H29: =IF(OR(B29=0,C29="",D29=""),0,IF(OR(AND(C29>=4,D29>=4),AND(C29<=2,D29<=2)),1,0)) -> 0 | I29: =IF(B29=0,"",IF(OR(G29=1,H29=1),0,1))
A30: =IF(COUNT('2 Import Main'!C30:DB30)=0,"",30) | B30: =COUNT('2 Import Main'!C30:DB30) -> 0 | C30: =IFERROR(AVERAGEIF('2 Import Main'!$C$3:$DB$3,"F",'2 Import Main'!C30:DB30),"") | D30: =IFERROR(AVERAGEIF('2 Import Main'!$C$3:$DB$3,"R",'2 Import Main'!C30:DB30),"") | E30: =IFERROR(MAX('2 Import Main'!C30:DB30),"") -> 0 | F30: =IFERROR(MIN('2 Import Main'!C30:DB30),"") -> 0 | G30: =IF(B30=0,"",IF(E30=F30,1,0)) | H30: =IF(OR(B30=0,C30="",D30=""),0,IF(OR(AND(C30>=4,D30>=4),AND(C30<=2,D30<=2)),1,0)) -> 0 | I30: =IF(B30=0,"",IF(OR(G30=1,H30=1),0,1))
A31: =IF(COUNT('2 Import Main'!C31:DB31)=0,"",31) | B31: =COUNT('2 Import Main'!C31:DB31) -> 0 | C31: =IFERROR(AVERAGEIF('2 Import Main'!$C$3:$DB$3,"F",'2 Import Main'!C31:DB31),"") | D31: =IFERROR(AVERAGEIF('2 Import Main'!$C$3:$DB$3,"R",'2 Import Main'!C31:DB31),"") | E31: =IFERROR(MAX('2 Import Main'!C31:DB31),"") -> 0 | F31: =IFERROR(MIN('2 Import Main'!C31:DB31),"") -> 0 | G31: =IF(B31=0,"",IF(E31=F31,1,0)) | H31: =IF(OR(B31=0,C31="",D31=""),0,IF(OR(AND(C31>=4,D31>=4),AND(C31<=2,D31<=2)),1,0)) -> 0 | I31: =IF(B31=0,"",IF(OR(G31=1,H31=1),0,1))
A32: =IF(COUNT('2 Import Main'!C32:DB32)=0,"",32) | B32: =COUNT('2 Import Main'!C32:DB32) -> 0 | C32: =IFERROR(AVERAGEIF('2 Import Main'!$C$3:$DB$3,"F",'2 Import Main'!C32:DB32),"") | D32: =IFERROR(AVERAGEIF('2 Import Main'!$C$3:$DB$3,"R",'2 Import Main'!C32:DB32),"") | E32: =IFERROR(MAX('2 Import Main'!C32:DB32),"") -> 0 | F32: =IFERROR(MIN('2 Import Main'!C32:DB32),"") -> 0 | G32: =IF(B32=0,"",IF(E32=F32,1,0)) | H32: =IF(OR(B32=0,C32="",D32=""),0,IF(OR(AND(C32>=4,D32>=4),AND(C32<=2,D32<=2)),1,0)) -> 0 | I32: =IF(B32=0,"",IF(OR(G32=1,H32=1),0,1))
A33: =IF(COUNT('2 Import Main'!C33:DB33)=0,"",33) | B33: =COUNT('2 Import Main'!C33:DB33) -> 0 | C33: =IFERROR(AVERAGEIF('2 Import Main'!$C$3:$DB$3,"F",'2 Import Main'!C33:DB33),"") | D33: =IFERROR(AVERAGEIF('2 Import Main'!$C$3:$DB$3,"R",'2 Import Main'!C33:DB33),"") | E33: =IFERROR(MAX('2 Import Main'!C33:DB33),"") -> 0 | F33: =IFERROR(MIN('2 Import Main'!C33:DB33),"") -> 0 | G33: =IF(B33=0,"",IF(E33=F33,1,0)) | H33: =IF(OR(B33=0,C33="",D33=""),0,IF(OR(AND(C33>=4,D33>=4),AND(C33<=2,D33<=2)),1,0)) -> 0 | I33: =IF(B33=0,"",IF(OR(G33=1,H33=1),0,1))
A34: =IF(COUNT('2 Import Main'!C34:DB34)=0,"",34) | B34: =COUNT('2 Import Main'!C34:DB34) -> 0 | C34: =IFERROR(AVERAGEIF('2 Import Main'!$C$3:$DB$3,"F",'2 Import Main'!C34:DB34),"") | D34: =IFERROR(AVERAGEIF('2 Import Main'!$C$3:$DB$3,"R",'2 Import Main'!C34:DB34),"") | E34: =IFERROR(MAX('2 Import Main'!C34:DB34),"") -> 0 | F34: =IFERROR(MIN('2 Import Main'!C34:DB34),"") -> 0 | G34: =IF(B34=0,"",IF(E34=F34,1,0)) | H34: =IF(OR(B34=0,C34="",D34=""),0,IF(OR(AND(C34>=4,D34>=4),AND(C34<=2,D34<=2)),1,0)) -> 0 | I34: =IF(B34=0,"",IF(OR(G34=1,H34=1),0,1))
A35: =IF(COUNT('2 Import Main'!C35:DB35)=0,"",35) | B35: =COUNT('2 Import Main'!C35:DB35) -> 0 | C35: =IFERROR(AVERAGEIF('2 Import Main'!$C$3:$DB$3,"F",'2 Import Main'!C35:DB35),"") | D35: =IFERROR(AVERAGEIF('2 Import Main'!$C$3:$DB$3,"R",'2 Import Main'!C35:DB35),"") | E35: =IFERROR(MAX('2 Import Main'!C35:DB35),"") -> 0 | F35: =IFERROR(MIN('2 Import Main'!C35:DB35),"") -> 0 | G35: =IF(B35=0,"",IF(E35=F35,1,0)) | H35: =IF(OR(B35=0,C35="",D35=""),0,IF(OR(AND(C35>=4,D35>=4),AND(C35<=2,D35<=2)),1,0)) -> 0 | I35: =IF(B35=0,"",IF(OR(G35=1,H35=1),0,1))
A36: =IF(COUNT('2 Import Main'!C36:DB36)=0,"",36) | B36: =COUNT('2 Import Main'!C36:DB36) -> 0 | C36: =IFERROR(AVERAGEIF('2 Import Main'!$C$3:$DB$3,"F",'2 Import Main'!C36:DB36),"") | D36: =IFERROR(AVERAGEIF('2 Import Main'!$C$3:$DB$3,"R",'2 Import Main'!C36:DB36),"") | E36: =IFERROR(MAX('2 Import Main'!C36:DB36),"") -> 0 | F36: =IFERROR(MIN('2 Import Main'!C36:DB36),"") -> 0 | G36: =IF(B36=0,"",IF(E36=F36,1,0)) | H36: =IF(OR(B36=0,C36="",D36=""),0,IF(OR(AND(C36>=4,D36>=4),AND(C36<=2,D36<=2)),1,0)) -> 0 | I36: =IF(B36=0,"",IF(OR(G36=1,H36=1),0,1))
A37: =IF(COUNT('2 Import Main'!C37:DB37)=0,"",37) | B37: =COUNT('2 Import Main'!C37:DB37) -> 0 | C37: =IFERROR(AVERAGEIF('2 Import Main'!$C$3:$DB$3,"F",'2 Import Main'!C37:DB37),"") | D37: =IFERROR(AVERAGEIF('2 Import Main'!$C$3:$DB$3,"R",'2 Import Main'!C37:DB37),"") | E37: =IFERROR(MAX('2 Import Main'!C37:DB37),"") -> 0 | F37: =IFERROR(MIN('2 Import Main'!C37:DB37),"") -> 0 | G37: =IF(B37=0,"",IF(E37=F37,1,0)) | H37: =IF(OR(B37=0,C37="",D37=""),0,IF(OR(AND(C37>=4,D37>=4),AND(C37<=2,D37<=2)),1,0)) -> 0 | I37: =IF(B37=0,"",IF(OR(G37=1,H37=1),0,1))
A38: =IF(COUNT('2 Import Main'!C38:DB38)=0,"",38) | B38: =COUNT('2 Import Main'!C38:DB38) -> 0 | C38: =IFERROR(AVERAGEIF('2 Import Main'!$C$3:$DB$3,"F",'2 Import Main'!C38:DB38),"") | D38: =IFERROR(AVERAGEIF('2 Import Main'!$C$3:$DB$3,"R",'2 Import Main'!C38:DB38),"") | E38: =IFERROR(MAX('2 Import Main'!C38:DB38),"") -> 0 | F38: =IFERROR(MIN('2 Import Main'!C38:DB38),"") -> 0 | G38: =IF(B38=0,"",IF(E38=F38,1,0)) | H38: =IF(OR(B38=0,C38="",D38=""),0,IF(OR(AND(C38>=4,D38>=4),AND(C38<=2,D38<=2)),1,0)) -> 0 | I38: =IF(B38=0,"",IF(OR(G38=1,H38=1),0,1))
A39: =IF(COUNT('2 Import Main'!C39:DB39)=0,"",39) | B39: =COUNT('2 Import Main'!C39:DB39) -> 0 | C39: =IFERROR(AVERAGEIF('2 Import Main'!$C$3:$DB$3,"F",'2 Import Main'!C39:DB39),"") | D39: =IFERROR(AVERAGEIF('2 Import Main'!$C$3:$DB$3,"R",'2 Import Main'!C39:DB39),"") | E39: =IFERROR(MAX('2 Import Main'!C39:DB39),"") -> 0 | F39: =IFERROR(MIN('2 Import Main'!C39:DB39),"") -> 0 | G39: =IF(B39=0,"",IF(E39=F39,1,0)) | H39: =IF(OR(B39=0,C39="",D39=""),0,IF(OR(AND(C39>=4,D39>=4),AND(C39<=2,D39<=2)),1,0)) -> 0 | I39: =IF(B39=0,"",IF(OR(G39=1,H39=1),0,1))
A40: =IF(COUNT('2 Import Main'!C40:DB40)=0,"",40) | B40: =COUNT('2 Import Main'!C40:DB40) -> 0 | C40: =IFERROR(AVERAGEIF('2 Import Main'!$C$3:$DB$3,"F",'2 Import Main'!C40:DB40),"") | D40: =IFERROR(AVERAGEIF('2 Import Main'!$C$3:$DB$3,"R",'2 Import Main'!C40:DB40),"") | E40: =IFERROR(MAX('2 Import Main'!C40:DB40),"") -> 0 | F40: =IFERROR(MIN('2 Import Main'!C40:DB40),"") -> 0 | G40: =IF(B40=0,"",IF(E40=F40,1,0)) | H40: =IF(OR(B40=0,C40="",D40=""),0,IF(OR(AND(C40>=4,D40>=4),AND(C40<=2,D40<=2)),1,0)) -> 0 | I40: =IF(B40=0,"",IF(OR(G40=1,H40=1),0,1))
A41: =IF(COUNT('2 Import Main'!C41:DB41)=0,"",41) | B41: =COUNT('2 Import Main'!C41:DB41) -> 0 | C41: =IFERROR(AVERAGEIF('2 Import Main'!$C$3:$DB$3,"F",'2 Import Main'!C41:DB41),"") | D41: =IFERROR(AVERAGEIF('2 Import Main'!$C$3:$DB$3,"R",'2 Import Main'!C41:DB41),"") | E41: =IFERROR(MAX('2 Import Main'!C41:DB41),"") -> 0 | F41: =IFERROR(MIN('2 Import Main'!C41:DB41),"") -> 0 | G41: =IF(B41=0,"",IF(E41=F41,1,0)) | H41: =IF(OR(B41=0,C41="",D41=""),0,IF(OR(AND(C41>=4,D41>=4),AND(C41<=2,D41<=2)),1,0)) -> 0 | I41: =IF(B41=0,"",IF(OR(G41=1,H41=1),0,1))
...

Sheet 8 Type A Means
A1: Type A Item Means (raw, un-flipped)
A2: Mean per item over VALID respondents, 1.00-5.00. The Diagnostic Workbook flips reverse items and applies (mean-1)x25. Do not flip or convert here.
A4: Sub-dimension | B4: Item | C4: Raw mean | D4: Reverse? | E4: Response rate | F4: Flag
A5: C4 | B5: CII-01 | C5: =IFERROR(AVERAGEIFS('2 Import Main'!C5:C204,'7 Screening'!$I$5:$I$204,1),"") | E5: =IF('1 Setup & Keys'!$B$20="","",IFERROR(COUNTIFS('7 Screening'!$I$5:$I$204,1,'2 Import Main'!C5:C204,"<>")/'1 Setup & Keys'!$B$20,"")) | F5: =IF($E$5="","",IF($E$5<Reference!$B$5,"LOW",""))
A6: C4 | B6: CII-02 | C6: =IFERROR(AVERAGEIFS('2 Import Main'!D5:D204,'7 Screening'!$I$5:$I$204,1),"")
A7: C4 | B7: CII-03 | C7: =IFERROR(AVERAGEIFS('2 Import Main'!E5:E204,'7 Screening'!$I$5:$I$204,1),"")
A8: C4 | B8: CII-04 | C8: =IFERROR(AVERAGEIFS('2 Import Main'!F5:F204,'7 Screening'!$I$5:$I$204,1),"")
A9: C4 | B9: CII-05 | C9: =IFERROR(AVERAGEIFS('2 Import Main'!G5:G204,'7 Screening'!$I$5:$I$204,1),"") | D9: R
A10: C4 | B10: CII-06 | C10: =IFERROR(AVERAGEIFS('2 Import Main'!H5:H204,'7 Screening'!$I$5:$I$204,1),"")
A11: C4 | B11: CII-07 | C11: =IFERROR(AVERAGEIFS('2 Import Main'!I5:I204,'7 Screening'!$I$5:$I$204,1),"")
A12: C4 | B12: CII-08 | C12: =IFERROR(AVERAGEIFS('2 Import Main'!J5:J204,'7 Screening'!$I$5:$I$204,1),"")
A13: C4 | B13: CII-09 | C13: =IFERROR(AVERAGEIFS('2 Import Main'!K5:K204,'7 Screening'!$I$5:$I$204,1),"")
A14: C4 | B14: CII-10 | C14: =IFERROR(AVERAGEIFS('2 Import Main'!L5:L204,'7 Screening'!$I$5:$I$204,1),"") | D14: R
A15: C4 | B15: CII-11 | C15: =IFERROR(AVERAGEIFS('2 Import Main'!M5:M204,'7 Screening'!$I$5:$I$204,1),"")
A16: C4 | B16: CII-12 | C16: =IFERROR(AVERAGEIFS('2 Import Main'!N5:N204,'7 Screening'!$I$5:$I$204,1),"")
A17: C4 | B17: CII-13 | C17: =IFERROR(AVERAGEIFS('2 Import Main'!O5:O204,'7 Screening'!$I$5:$I$204,1),"")
A18: C4 | B18: CII-14 | C18: =IFERROR(AVERAGEIFS('2 Import Main'!P5:P204,'7 Screening'!$I$5:$I$204,1),"")
A19: C4 | B19: CII-15 | C19: =IFERROR(AVERAGEIFS('2 Import Main'!Q5:Q204,'7 Screening'!$I$5:$I$204,1),"") | D19: R
A20: M1 | B20: MI1-01 | C20: =IFERROR(AVERAGEIFS('2 Import Main'!R5:R204,'7 Screening'!$I$5:$I$204,1),"") | E20: =IF('1 Setup & Keys'!$B$20="","",IFERROR(COUNTIFS('7 Screening'!$I$5:$I$204,1,'2 Import Main'!R5:R204,"<>")/'1 Setup & Keys'!$B$20,"")) | F20: =IF($E$20="","",IF($E$20<Reference!$B$5,"LOW",""))
A21: M1 | B21: MI1-02 | C21: =IFERROR(AVERAGEIFS('2 Import Main'!S5:S204,'7 Screening'!$I$5:$I$204,1),"")
A22: M1 | B22: MI1-03 | C22: =IFERROR(AVERAGEIFS('2 Import Main'!T5:T204,'7 Screening'!$I$5:$I$204,1),"")
A23: M1 | B23: MI1-04 | C23: =IFERROR(AVERAGEIFS('2 Import Main'!U5:U204,'7 Screening'!$I$5:$I$204,1),"") | D23: R
A24: M1 | B24: MI1-05 | C24: =IFERROR(AVERAGEIFS('2 Import Main'!V5:V204,'7 Screening'!$I$5:$I$204,1),"")
A25: M1 | B25: MI1-06 | C25: =IFERROR(AVERAGEIFS('2 Import Main'!W5:W204,'7 Screening'!$I$5:$I$204,1),"")
A26: M1 | B26: MI1-07 | C26: =IFERROR(AVERAGEIFS('2 Import Main'!X5:X204,'7 Screening'!$I$5:$I$204,1),"")
A27: M1 | B27: MI1-08 | C27: =IFERROR(AVERAGEIFS('2 Import Main'!Y5:Y204,'7 Screening'!$I$5:$I$204,1),"")
A28: M2 | B28: MI2-01 | C28: =IFERROR(AVERAGEIFS('2 Import Main'!Z5:Z204,'7 Screening'!$I$5:$I$204,1),"") | E28: =IF('1 Setup & Keys'!$B$20="","",IFERROR(COUNTIFS('7 Screening'!$I$5:$I$204,1,'2 Import Main'!Z5:Z204,"<>")/'1 Setup & Keys'!$B$20,"")) | F28: =IF($E$28="","",IF($E$28<Reference!$B$5,"LOW",""))
A29: M2 | B29: MI2-02 | C29: =IFERROR(AVERAGEIFS('2 Import Main'!AA5:AA204,'7 Screening'!$I$5:$I$204,1),"")
A30: M2 | B30: MI2-03 | C30: =IFERROR(AVERAGEIFS('2 Import Main'!AB5:AB204,'7 Screening'!$I$5:$I$204,1),"")
A31: M2 | B31: MI2-04 | C31: =IFERROR(AVERAGEIFS('2 Import Main'!AC5:AC204,'7 Screening'!$I$5:$I$204,1),"")
A32: M2 | B32: MI2-05 | C32: =IFERROR(AVERAGEIFS('2 Import Main'!AD5:AD204,'7 Screening'!$I$5:$I$204,1),"") | D32: R
A33: M3 | B33: MI3-01 | C33: =IFERROR(AVERAGEIFS('2 Import Main'!AE5:AE204,'7 Screening'!$I$5:$I$204,1),"") | E33: =IF('1 Setup & Keys'!$B$20="","",IFERROR(COUNTIFS('7 Screening'!$I$5:$I$204,1,'2 Import Main'!AE5:AE204,"<>")/'1 Setup & Keys'!$B$20,"")) | F33: =IF($E$33="","",IF($E$33<Reference!$B$5,"LOW",""))
A34: M3 | B34: MI3-02 | C34: =IFERROR(AVERAGEIFS('2 Import Main'!AF5:AF204,'7 Screening'!$I$5:$I$204,1),"")
A35: M3 | B35: MI3-03 | C35: =IFERROR(AVERAGEIFS('2 Import Main'!AG5:AG204,'7 Screening'!$I$5:$I$204,1),"")
A36: M3 | B36: MI3-04 | C36: =IFERROR(AVERAGEIFS('2 Import Main'!AH5:AH204,'7 Screening'!$I$5:$I$204,1),"") | D36: R
A37: M3 | B37: MI3-05 | C37: =IFERROR(AVERAGEIFS('2 Import Main'!AI5:AI204,'7 Screening'!$I$5:$I$204,1),"")
A38: M4 | B38: MI4-01 | C38: =IFERROR(AVERAGEIFS('2 Import Main'!AJ5:AJ204,'7 Screening'!$I$5:$I$204,1),"") | E38: =IF('1 Setup & Keys'!$B$20="","",IFERROR(COUNTIFS('7 Screening'!$I$5:$I$204,1,'2 Import Main'!AJ5:AJ204,"<>")/'1 Setup & Keys'!$B$20,"")) | F38: =IF($E$38="","",IF($E$38<Reference!$B$5,"LOW",""))
A39: M4 | B39: MI4-02 | C39: =IFERROR(AVERAGEIFS('2 Import Main'!AK5:AK204,'7 Screening'!$I$5:$I$204,1),"")
A40: M4 | B40: MI4-03 | C40: =IFERROR(AVERAGEIFS('2 Import Main'!AL5:AL204,'7 Screening'!$I$5:$I$204,1),"")
A41: M4 | B41: MI4-04 | C41: =IFERROR(AVERAGEIFS('2 Import Main'!AM5:AM204,'7 Screening'!$I$5:$I$204,1),"") | D41: R
...

Sheet 9 Type C Scoring
A1: Type C Module Scoring (finished 0-100 unless noted)
A2: Bespoke module rules (Tier 3 Module Library). House convention (mean-1)x25. Reverse items flipped HERE because these are finished scores, not Type A means.
A4: 6.1 M-O1-LT — Decision Rights (leadership)
A5: Decision type | B5: n | C5: agreeR | D5: agreeA | E5: agreeP | F5: agreeI | G5: agreeD | H5: Dec. agree
A6: =IF('1 Setup & Keys'!$D$32="","",'1 Setup & Keys'!$D$32) | B6: =IF('1 Setup & Keys'!$D$32="","",COUNTIFS('4 Import Leadership'!$B$5:$B$154,'1 Setup & Keys'!$D$32)) | C6: =IF(OR('1 Setup & Keys'!$D$32="",$B6=0),"",IFERROR(SUMPRODUCT(MAX(('4 Import Leadership'!$B$5:$B$154='1 Setup & Keys'!$D$32)*N('4 Import Leadership'!$I$5:$I$154)))/$B6,"")) | D6: =IF(OR('1 Setup & Keys'!$D$32="",$B6=0),"",IFERROR(SUMPRODUCT(MAX(('4 Import Leadership'!$B$5:$B$154='1 Setup & Keys'!$D$32)*N('4 Import Leadership'!$J$5:$J$154)))/$B6,"")) | E6: =IF(OR('1 Setup & Keys'!$D$32="",$B6=0),"",IFERROR(SUMPRODUCT(MAX(('4 Import Leadership'!$B$5:$B$154='1 Setup & Keys'!$D$32)*N('4 Import Leadership'!$K$5:$K$154)))/$B6,"")) | F6: =IF(OR('1 Setup & Keys'!$D$32="",$B6=0),"",IFERROR(SUMPRODUCT(MAX(('4 Import Leadership'!$B$5:$B$154='1 Setup & Keys'!$D$32)*N('4 Import Leadership'!$L$5:$L$154)))/$B6,"")) | G6: =IF(OR('1 Setup & Keys'!$D$32="",$B6=0),"",IFERROR(SUMPRODUCT(MAX(('4 Import Leadership'!$B$5:$B$154='1 Setup & Keys'!$D$32)*N('4 Import Leadership'!$M$5:$M$154)))/$B6,"")) | H6: =IF('1 Setup & Keys'!$D$32="","",IFERROR(AVERAGE(C6:G6),""))
A7: =IF('1 Setup & Keys'!$D$33="","",'1 Setup & Keys'!$D$33) | B7: =IF('1 Setup & Keys'!$D$33="","",COUNTIFS('4 Import Leadership'!$B$5:$B$154,'1 Setup & Keys'!$D$33)) | C7: =IF(OR('1 Setup & Keys'!$D$33="",$B7=0),"",IFERROR(SUMPRODUCT(MAX(('4 Import Leadership'!$B$5:$B$154='1 Setup & Keys'!$D$33)*N('4 Import Leadership'!$I$5:$I$154)))/$B7,"")) | D7: =IF(OR('1 Setup & Keys'!$D$33="",$B7=0),"",IFERROR(SUMPRODUCT(MAX(('4 Import Leadership'!$B$5:$B$154='1 Setup & Keys'!$D$33)*N('4 Import Leadership'!$J$5:$J$154)))/$B7,"")) | E7: =IF(OR('1 Setup & Keys'!$D$33="",$B7=0),"",IFERROR(SUMPRODUCT(MAX(('4 Import Leadership'!$B$5:$B$154='1 Setup & Keys'!$D$33)*N('4 Import Leadership'!$K$5:$K$154)))/$B7,"")) | F7: =IF(OR('1 Setup & Keys'!$D$33="",$B7=0),"",IFERROR(SUMPRODUCT(MAX(('4 Import Leadership'!$B$5:$B$154='1 Setup & Keys'!$D$33)*N('4 Import Leadership'!$L$5:$L$154)))/$B7,"")) | G7: =IF(OR('1 Setup & Keys'!$D$33="",$B7=0),"",IFERROR(SUMPRODUCT(MAX(('4 Import Leadership'!$B$5:$B$154='1 Setup & Keys'!$D$33)*N('4 Import Leadership'!$M$5:$M$154)))/$B7,"")) | H7: =IF('1 Setup & Keys'!$D$33="","",IFERROR(AVERAGE(C7:G7),""))
A8: =IF('1 Setup & Keys'!$D$34="","",'1 Setup & Keys'!$D$34) | B8: =IF('1 Setup & Keys'!$D$34="","",COUNTIFS('4 Import Leadership'!$B$5:$B$154,'1 Setup & Keys'!$D$34)) | C8: =IF(OR('1 Setup & Keys'!$D$34="",$B8=0),"",IFERROR(SUMPRODUCT(MAX(('4 Import Leadership'!$B$5:$B$154='1 Setup & Keys'!$D$34)*N('4 Import Leadership'!$I$5:$I$154)))/$B8,"")) | D8: =IF(OR('1 Setup & Keys'!$D$34="",$B8=0),"",IFERROR(SUMPRODUCT(MAX(('4 Import Leadership'!$B$5:$B$154='1 Setup & Keys'!$D$34)*N('4 Import Leadership'!$J$5:$J$154)))/$B8,"")) | E8: =IF(OR('1 Setup & Keys'!$D$34="",$B8=0),"",IFERROR(SUMPRODUCT(MAX(('4 Import Leadership'!$B$5:$B$154='1 Setup & Keys'!$D$34)*N('4 Import Leadership'!$K$5:$K$154)))/$B8,"")) | F8: =IF(OR('1 Setup & Keys'!$D$34="",$B8=0),"",IFERROR(SUMPRODUCT(MAX(('4 Import Leadership'!$B$5:$B$154='1 Setup & Keys'!$D$34)*N('4 Import Leadership'!$L$5:$L$154)))/$B8,"")) | G8: =IF(OR('1 Setup & Keys'!$D$34="",$B8=0),"",IFERROR(SUMPRODUCT(MAX(('4 Import Leadership'!$B$5:$B$154='1 Setup & Keys'!$D$34)*N('4 Import Leadership'!$M$5:$M$154)))/$B8,"")) | H8: =IF('1 Setup & Keys'!$D$34="","",IFERROR(AVERAGE(C8:G8),""))
A9: =IF('1 Setup & Keys'!$D$35="","",'1 Setup & Keys'!$D$35) | B9: =IF('1 Setup & Keys'!$D$35="","",COUNTIFS('4 Import Leadership'!$B$5:$B$154,'1 Setup & Keys'!$D$35)) | C9: =IF(OR('1 Setup & Keys'!$D$35="",$B9=0),"",IFERROR(SUMPRODUCT(MAX(('4 Import Leadership'!$B$5:$B$154='1 Setup & Keys'!$D$35)*N('4 Import Leadership'!$I$5:$I$154)))/$B9,"")) | D9: =IF(OR('1 Setup & Keys'!$D$35="",$B9=0),"",IFERROR(SUMPRODUCT(MAX(('4 Import Leadership'!$B$5:$B$154='1 Setup & Keys'!$D$35)*N('4 Import Leadership'!$J$5:$J$154)))/$B9,"")) | E9: =IF(OR('1 Setup & Keys'!$D$35="",$B9=0),"",IFERROR(SUMPRODUCT(MAX(('4 Import Leadership'!$B$5:$B$154='1 Setup & Keys'!$D$35)*N('4 Import Leadership'!$K$5:$K$154)))/$B9,"")) | F9: =IF(OR('1 Setup & Keys'!$D$35="",$B9=0),"",IFERROR(SUMPRODUCT(MAX(('4 Import Leadership'!$B$5:$B$154='1 Setup & Keys'!$D$35)*N('4 Import Leadership'!$L$5:$L$154)))/$B9,"")) | G9: =IF(OR('1 Setup & Keys'!$D$35="",$B9=0),"",IFERROR(SUMPRODUCT(MAX(('4 Import Leadership'!$B$5:$B$154='1 Setup & Keys'!$D$35)*N('4 Import Leadership'!$M$5:$M$154)))/$B9,"")) | H9: =IF('1 Setup & Keys'!$D$35="","",IFERROR(AVERAGE(C9:G9),""))
A10: =IF('1 Setup & Keys'!$D$36="","",'1 Setup & Keys'!$D$36) | B10: =IF('1 Setup & Keys'!$D$36="","",COUNTIFS('4 Import Leadership'!$B$5:$B$154,'1 Setup & Keys'!$D$36)) | C10: =IF(OR('1 Setup & Keys'!$D$36="",$B10=0),"",IFERROR(SUMPRODUCT(MAX(('4 Import Leadership'!$B$5:$B$154='1 Setup & Keys'!$D$36)*N('4 Import Leadership'!$I$5:$I$154)))/$B10,"")) | D10: =IF(OR('1 Setup & Keys'!$D$36="",$B10=0),"",IFERROR(SUMPRODUCT(MAX(('4 Import Leadership'!$B$5:$B$154='1 Setup & Keys'!$D$36)*N('4 Import Leadership'!$J$5:$J$154)))/$B10,"")) | E10: =IF(OR('1 Setup & Keys'!$D$36="",$B10=0),"",IFERROR(SUMPRODUCT(MAX(('4 Import Leadership'!$B$5:$B$154='1 Setup & Keys'!$D$36)*N('4 Import Leadership'!$K$5:$K$154)))/$B10,"")) | F10: =IF(OR('1 Setup & Keys'!$D$36="",$B10=0),"",IFERROR(SUMPRODUCT(MAX(('4 Import Leadership'!$B$5:$B$154='1 Setup & Keys'!$D$36)*N('4 Import Leadership'!$L$5:$L$154)))/$B10,"")) | G10: =IF(OR('1 Setup & Keys'!$D$36="",$B10=0),"",IFERROR(SUMPRODUCT(MAX(('4 Import Leadership'!$B$5:$B$154='1 Setup & Keys'!$D$36)*N('4 Import Leadership'!$M$5:$M$154)))/$B10,"")) | H10: =IF('1 Setup & Keys'!$D$36="","",IFERROR(AVERAGE(C10:G10),""))
A11: =IF('1 Setup & Keys'!$D$37="","",'1 Setup & Keys'!$D$37) | B11: =IF('1 Setup & Keys'!$D$37="","",COUNTIFS('4 Import Leadership'!$B$5:$B$154,'1 Setup & Keys'!$D$37)) | C11: =IF(OR('1 Setup & Keys'!$D$37="",$B11=0),"",IFERROR(SUMPRODUCT(MAX(('4 Import Leadership'!$B$5:$B$154='1 Setup & Keys'!$D$37)*N('4 Import Leadership'!$I$5:$I$154)))/$B11,"")) | D11: =IF(OR('1 Setup & Keys'!$D$37="",$B11=0),"",IFERROR(SUMPRODUCT(MAX(('4 Import Leadership'!$B$5:$B$154='1 Setup & Keys'!$D$37)*N('4 Import Leadership'!$J$5:$J$154)))/$B11,"")) | E11: =IF(OR('1 Setup & Keys'!$D$37="",$B11=0),"",IFERROR(SUMPRODUCT(MAX(('4 Import Leadership'!$B$5:$B$154='1 Setup & Keys'!$D$37)*N('4 Import Leadership'!$K$5:$K$154)))/$B11,"")) | F11: =IF(OR('1 Setup & Keys'!$D$37="",$B11=0),"",IFERROR(SUMPRODUCT(MAX(('4 Import Leadership'!$B$5:$B$154='1 Setup & Keys'!$D$37)*N('4 Import Leadership'!$L$5:$L$154)))/$B11,"")) | G11: =IF(OR('1 Setup & Keys'!$D$37="",$B11=0),"",IFERROR(SUMPRODUCT(MAX(('4 Import Leadership'!$B$5:$B$154='1 Setup & Keys'!$D$37)*N('4 Import Leadership'!$M$5:$M$154)))/$B11,"")) | H11: =IF('1 Setup & Keys'!$D$37="","",IFERROR(AVERAGE(C11:G11),""))
A12: =IF('1 Setup & Keys'!$D$38="","",'1 Setup & Keys'!$D$38) | B12: =IF('1 Setup & Keys'!$D$38="","",COUNTIFS('4 Import Leadership'!$B$5:$B$154,'1 Setup & Keys'!$D$38)) | C12: =IF(OR('1 Setup & Keys'!$D$38="",$B12=0),"",IFERROR(SUMPRODUCT(MAX(('4 Import Leadership'!$B$5:$B$154='1 Setup & Keys'!$D$38)*N('4 Import Leadership'!$I$5:$I$154)))/$B12,"")) | D12: =IF(OR('1 Setup & Keys'!$D$38="",$B12=0),"",IFERROR(SUMPRODUCT(MAX(('4 Import Leadership'!$B$5:$B$154='1 Setup & Keys'!$D$38)*N('4 Import Leadership'!$J$5:$J$154)))/$B12,"")) | E12: =IF(OR('1 Setup & Keys'!$D$38="",$B12=0),"",IFERROR(SUMPRODUCT(MAX(('4 Import Leadership'!$B$5:$B$154='1 Setup & Keys'!$D$38)*N('4 Import Leadership'!$K$5:$K$154)))/$B12,"")) | F12: =IF(OR('1 Setup & Keys'!$D$38="",$B12=0),"",IFERROR(SUMPRODUCT(MAX(('4 Import Leadership'!$B$5:$B$154='1 Setup & Keys'!$D$38)*N('4 Import Leadership'!$L$5:$L$154)))/$B12,"")) | G12: =IF(OR('1 Setup & Keys'!$D$38="",$B12=0),"",IFERROR(SUMPRODUCT(MAX(('4 Import Leadership'!$B$5:$B$154='1 Setup & Keys'!$D$38)*N('4 Import Leadership'!$M$5:$M$154)))/$B12,"")) | H12: =IF('1 Setup & Keys'!$D$38="","",IFERROR(AVERAGE(C12:G12),""))
A13: =IF('1 Setup & Keys'!$D$39="","",'1 Setup & Keys'!$D$39) | B13: =IF('1 Setup & Keys'!$D$39="","",COUNTIFS('4 Import Leadership'!$B$5:$B$154,'1 Setup & Keys'!$D$39)) | C13: =IF(OR('1 Setup & Keys'!$D$39="",$B13=0),"",IFERROR(SUMPRODUCT(MAX(('4 Import Leadership'!$B$5:$B$154='1 Setup & Keys'!$D$39)*N('4 Import Leadership'!$I$5:$I$154)))/$B13,"")) | D13: =IF(OR('1 Setup & Keys'!$D$39="",$B13=0),"",IFERROR(SUMPRODUCT(MAX(('4 Import Leadership'!$B$5:$B$154='1 Setup & Keys'!$D$39)*N('4 Import Leadership'!$J$5:$J$154)))/$B13,"")) | E13: =IF(OR('1 Setup & Keys'!$D$39="",$B13=0),"",IFERROR(SUMPRODUCT(MAX(('4 Import Leadership'!$B$5:$B$154='1 Setup & Keys'!$D$39)*N('4 Import Leadership'!$K$5:$K$154)))/$B13,"")) | F13: =IF(OR('1 Setup & Keys'!$D$39="",$B13=0),"",IFERROR(SUMPRODUCT(MAX(('4 Import Leadership'!$B$5:$B$154='1 Setup & Keys'!$D$39)*N('4 Import Leadership'!$L$5:$L$154)))/$B13,"")) | G13: =IF(OR('1 Setup & Keys'!$D$39="",$B13=0),"",IFERROR(SUMPRODUCT(MAX(('4 Import Leadership'!$B$5:$B$154='1 Setup & Keys'!$D$39)*N('4 Import Leadership'!$M$5:$M$154)))/$B13,"")) | H13: =IF('1 Setup & Keys'!$D$39="","",IFERROR(AVERAGE(C13:G13),""))
A14: =IF('1 Setup & Keys'!$D$40="","",'1 Setup & Keys'!$D$40) | B14: =IF('1 Setup & Keys'!$D$40="","",COUNTIFS('4 Import Leadership'!$B$5:$B$154,'1 Setup & Keys'!$D$40)) | C14: =IF(OR('1 Setup & Keys'!$D$40="",$B14=0),"",IFERROR(SUMPRODUCT(MAX(('4 Import Leadership'!$B$5:$B$154='1 Setup & Keys'!$D$40)*N('4 Import Leadership'!$I$5:$I$154)))/$B14,"")) | D14: =IF(OR('1 Setup & Keys'!$D$40="",$B14=0),"",IFERROR(SUMPRODUCT(MAX(('4 Import Leadership'!$B$5:$B$154='1 Setup & Keys'!$D$40)*N('4 Import Leadership'!$J$5:$J$154)))/$B14,"")) | E14: =IF(OR('1 Setup & Keys'!$D$40="",$B14=0),"",IFERROR(SUMPRODUCT(MAX(('4 Import Leadership'!$B$5:$B$154='1 Setup & Keys'!$D$40)*N('4 Import Leadership'!$K$5:$K$154)))/$B14,"")) | F14: =IF(OR('1 Setup & Keys'!$D$40="",$B14=0),"",IFERROR(SUMPRODUCT(MAX(('4 Import Leadership'!$B$5:$B$154='1 Setup & Keys'!$D$40)*N('4 Import Leadership'!$L$5:$L$154)))/$B14,"")) | G14: =IF(OR('1 Setup & Keys'!$D$40="",$B14=0),"",IFERROR(SUMPRODUCT(MAX(('4 Import Leadership'!$B$5:$B$154='1 Setup & Keys'!$D$40)*N('4 Import Leadership'!$M$5:$M$154)))/$B14,"")) | H14: =IF('1 Setup & Keys'!$D$40="","",IFERROR(AVERAGE(C14:G14),""))
A15: =IF('1 Setup & Keys'!$D$41="","",'1 Setup & Keys'!$D$41) | B15: =IF('1 Setup & Keys'!$D$41="","",COUNTIFS('4 Import Leadership'!$B$5:$B$154,'1 Setup & Keys'!$D$41)) | C15: =IF(OR('1 Setup & Keys'!$D$41="",$B15=0),"",IFERROR(SUMPRODUCT(MAX(('4 Import Leadership'!$B$5:$B$154='1 Setup & Keys'!$D$41)*N('4 Import Leadership'!$I$5:$I$154)))/$B15,"")) | D15: =IF(OR('1 Setup & Keys'!$D$41="",$B15=0),"",IFERROR(SUMPRODUCT(MAX(('4 Import Leadership'!$B$5:$B$154='1 Setup & Keys'!$D$41)*N('4 Import Leadership'!$J$5:$J$154)))/$B15,"")) | E15: =IF(OR('1 Setup & Keys'!$D$41="",$B15=0),"",IFERROR(SUMPRODUCT(MAX(('4 Import Leadership'!$B$5:$B$154='1 Setup & Keys'!$D$41)*N('4 Import Leadership'!$K$5:$K$154)))/$B15,"")) | F15: =IF(OR('1 Setup & Keys'!$D$41="",$B15=0),"",IFERROR(SUMPRODUCT(MAX(('4 Import Leadership'!$B$5:$B$154='1 Setup & Keys'!$D$41)*N('4 Import Leadership'!$L$5:$L$154)))/$B15,"")) | G15: =IF(OR('1 Setup & Keys'!$D$41="",$B15=0),"",IFERROR(SUMPRODUCT(MAX(('4 Import Leadership'!$B$5:$B$154='1 Setup & Keys'!$D$41)*N('4 Import Leadership'!$M$5:$M$154)))/$B15,"")) | H15: =IF('1 Setup & Keys'!$D$41="","",IFERROR(AVERAGE(C15:G15),""))
A16: =IF('1 Setup & Keys'!$D$42="","",'1 Setup & Keys'!$D$42) | B16: =IF('1 Setup & Keys'!$D$42="","",COUNTIFS('4 Import Leadership'!$B$5:$B$154,'1 Setup & Keys'!$D$42)) | C16: =IF(OR('1 Setup & Keys'!$D$42="",$B16=0),"",IFERROR(SUMPRODUCT(MAX(('4 Import Leadership'!$B$5:$B$154='1 Setup & Keys'!$D$42)*N('4 Import Leadership'!$I$5:$I$154)))/$B16,"")) | D16: =IF(OR('1 Setup & Keys'!$D$42="",$B16=0),"",IFERROR(SUMPRODUCT(MAX(('4 Import Leadership'!$B$5:$B$154='1 Setup & Keys'!$D$42)*N('4 Import Leadership'!$J$5:$J$154)))/$B16,"")) | E16: =IF(OR('1 Setup & Keys'!$D$42="",$B16=0),"",IFERROR(SUMPRODUCT(MAX(('4 Import Leadership'!$B$5:$B$154='1 Setup & Keys'!$D$42)*N('4 Import Leadership'!$K$5:$K$154)))/$B16,"")) | F16: =IF(OR('1 Setup & Keys'!$D$42="",$B16=0),"",IFERROR(SUMPRODUCT(MAX(('4 Import Leadership'!$B$5:$B$154='1 Setup & Keys'!$D$42)*N('4 Import Leadership'!$L$5:$L$154)))/$B16,"")) | G16: =IF(OR('1 Setup & Keys'!$D$42="",$B16=0),"",IFERROR(SUMPRODUCT(MAX(('4 Import Leadership'!$B$5:$B$154='1 Setup & Keys'!$D$42)*N('4 Import Leadership'!$M$5:$M$154)))/$B16,"")) | H16: =IF('1 Setup & Keys'!$D$42="","",IFERROR(AVERAGE(C16:G16),""))
A17: =IF('1 Setup & Keys'!$D$43="","",'1 Setup & Keys'!$D$43) | B17: =IF('1 Setup & Keys'!$D$43="","",COUNTIFS('4 Import Leadership'!$B$5:$B$154,'1 Setup & Keys'!$D$43)) | C17: =IF(OR('1 Setup & Keys'!$D$43="",$B17=0),"",IFERROR(SUMPRODUCT(MAX(('4 Import Leadership'!$B$5:$B$154='1 Setup & Keys'!$D$43)*N('4 Import Leadership'!$I$5:$I$154)))/$B17,"")) | D17: =IF(OR('1 Setup & Keys'!$D$43="",$B17=0),"",IFERROR(SUMPRODUCT(MAX(('4 Import Leadership'!$B$5:$B$154='1 Setup & Keys'!$D$43)*N('4 Import Leadership'!$J$5:$J$154)))/$B17,"")) | E17: =IF(OR('1 Setup & Keys'!$D$43="",$B17=0),"",IFERROR(SUMPRODUCT(MAX(('4 Import Leadership'!$B$5:$B$154='1 Setup & Keys'!$D$43)*N('4 Import Leadership'!$K$5:$K$154)))/$B17,"")) | F17: =IF(OR('1 Setup & Keys'!$D$43="",$B17=0),"",IFERROR(SUMPRODUCT(MAX(('4 Import Leadership'!$B$5:$B$154='1 Setup & Keys'!$D$43)*N('4 Import Leadership'!$L$5:$L$154)))/$B17,"")) | G17: =IF(OR('1 Setup & Keys'!$D$43="",$B17=0),"",IFERROR(SUMPRODUCT(MAX(('4 Import Leadership'!$B$5:$B$154='1 Setup & Keys'!$D$43)*N('4 Import Leadership'!$M$5:$M$154)))/$B17,"")) | H17: =IF('1 Setup & Keys'!$D$43="","",IFERROR(AVERAGE(C17:G17),""))
A19: Per-decision clarity (house convention)
A20: Decision type | B20: Clarity 0-100
A21: =IF('1 Setup & Keys'!$D$32="","",'1 Setup & Keys'!$D$32) | B21: =IF('1 Setup & Keys'!$D$32="","",IFERROR((AVERAGEIFS('4 Import Leadership'!$H$5:$H$154,'4 Import Leadership'!$B$5:$B$154,'1 Setup & Keys'!$D$32)-1)*25,""))
A22: =IF('1 Setup & Keys'!$D$33="","",'1 Setup & Keys'!$D$33) | B22: =IF('1 Setup & Keys'!$D$33="","",IFERROR((AVERAGEIFS('4 Import Leadership'!$H$5:$H$154,'4 Import Leadership'!$B$5:$B$154,'1 Setup & Keys'!$D$33)-1)*25,""))
A23: =IF('1 Setup & Keys'!$D$34="","",'1 Setup & Keys'!$D$34) | B23: =IF('1 Setup & Keys'!$D$34="","",IFERROR((AVERAGEIFS('4 Import Leadership'!$H$5:$H$154,'4 Import Leadership'!$B$5:$B$154,'1 Setup & Keys'!$D$34)-1)*25,""))
A24: =IF('1 Setup & Keys'!$D$35="","",'1 Setup & Keys'!$D$35) | B24: =IF('1 Setup & Keys'!$D$35="","",IFERROR((AVERAGEIFS('4 Import Leadership'!$H$5:$H$154,'4 Import Leadership'!$B$5:$B$154,'1 Setup & Keys'!$D$35)-1)*25,""))
A25: =IF('1 Setup & Keys'!$D$36="","",'1 Setup & Keys'!$D$36) | B25: =IF('1 Setup & Keys'!$D$36="","",IFERROR((AVERAGEIFS('4 Import Leadership'!$H$5:$H$154,'4 Import Leadership'!$B$5:$B$154,'1 Setup & Keys'!$D$36)-1)*25,""))
A26: =IF('1 Setup & Keys'!$D$37="","",'1 Setup & Keys'!$D$37) | B26: =IF('1 Setup & Keys'!$D$37="","",IFERROR((AVERAGEIFS('4 Import Leadership'!$H$5:$H$154,'4 Import Leadership'!$B$5:$B$154,'1 Setup & Keys'!$D$37)-1)*25,""))
A27: =IF('1 Setup & Keys'!$D$38="","",'1 Setup & Keys'!$D$38) | B27: =IF('1 Setup & Keys'!$D$38="","",IFERROR((AVERAGEIFS('4 Import Leadership'!$H$5:$H$154,'4 Import Leadership'!$B$5:$B$154,'1 Setup & Keys'!$D$38)-1)*25,""))
A28: =IF('1 Setup & Keys'!$D$39="","",'1 Setup & Keys'!$D$39) | B28: =IF('1 Setup & Keys'!$D$39="","",IFERROR((AVERAGEIFS('4 Import Leadership'!$H$5:$H$154,'4 Import Leadership'!$B$5:$B$154,'1 Setup & Keys'!$D$39)-1)*25,""))
A29: =IF('1 Setup & Keys'!$D$40="","",'1 Setup & Keys'!$D$40) | B29: =IF('1 Setup & Keys'!$D$40="","",IFERROR((AVERAGEIFS('4 Import Leadership'!$H$5:$H$154,'4 Import Leadership'!$B$5:$B$154,'1 Setup & Keys'!$D$40)-1)*25,""))
A30: =IF('1 Setup & Keys'!$D$41="","",'1 Setup & Keys'!$D$41) | B30: =IF('1 Setup & Keys'!$D$41="","",IFERROR((AVERAGEIFS('4 Import Leadership'!$H$5:$H$154,'4 Import Leadership'!$B$5:$B$154,'1 Setup & Keys'!$D$41)-1)*25,""))
A31: =IF('1 Setup & Keys'!$D$42="","",'1 Setup & Keys'!$D$42) | B31: =IF('1 Setup & Keys'!$D$42="","",IFERROR((AVERAGEIFS('4 Import Leadership'!$H$5:$H$154,'4 Import Leadership'!$B$5:$B$154,'1 Setup & Keys'!$D$42)-1)*25,""))
A32: =IF('1 Setup & Keys'!$D$43="","",'1 Setup & Keys'!$D$43) | B32: =IF('1 Setup & Keys'!$D$43="","",IFERROR((AVERAGEIFS('4 Import Leadership'!$H$5:$H$154,'4 Import Leadership'!$B$5:$B$154,'1 Setup & Keys'!$D$43)-1)*25,""))
A34: Aggregate agreement | B34: =IFERROR(AVERAGE(H6:H17),"")
A35: Aggregate clarity (0-100) | B35: =IFERROR(AVERAGE(B21:B32),"")
A36: Leadership response rate | B36: =IF('1 Setup & Keys'!$B$22="","",IFERROR(SUM('4 Import Leadership'!$N$5:$N$154)/'1 Setup & Keys'!$B$22,""))
A37: =IF($B36="","",IF($B36<Reference!$B$6,"LOW leadership response","ok"))
